[2025-06-14 07:12:37 +0000] [27856] [INFO] Starting gunicorn 23.0.0
[2025-06-14 07:12:37 +0000] [27856] [INFO] Listening at: http://0.0.0.0:8000 (27856)
[2025-06-14 07:12:37 +0000] [27856] [INFO] Using worker: sync
[2025-06-14 07:12:37 +0000] [27857] [INFO] Booting worker with pid: 27857
Invalid HTTP_HOST header: '13.203.155.208'. You may need to add '13.203.155.208' to ALLOWED_HOSTS.
Traceback (most recent call last):
  File "/home/ec2-user/intern_python/venv/lib64/python3.9/site-packages/django/core/handlers/exception.py", line 55, in inner
    response = get_response(request)
  File "/home/ec2-user/intern_python/venv/lib64/python3.9/site-packages/django/utils/deprecation.py", line 133, in __call__
    response = self.process_request(request)
  File "/home/ec2-user/intern_python/venv/lib64/python3.9/site-packages/django/middleware/common.py", line 48, in process_request
    host = request.get_host()
  File "/home/ec2-user/intern_python/venv/lib64/python3.9/site-packages/django/http/request.py", line 150, in get_host
    raise DisallowedHost(msg)
django.core.exceptions.DisallowedHost: Invalid HTTP_HOST header: '13.203.155.208'. You may need to add '13.203.155.208' to ALLOWED_HOSTS.
Invalid HTTP_HOST header: '13.203.155.208'. You may need to add '13.203.155.208' to ALLOWED_HOSTS.
Traceback (most recent call last):
  File "/home/ec2-user/intern_python/venv/lib64/python3.9/site-packages/django/core/handlers/exception.py", line 55, in inner
    response = get_response(request)
  File "/home/ec2-user/intern_python/venv/lib64/python3.9/site-packages/django/utils/deprecation.py", line 133, in __call__
    response = self.process_request(request)
  File "/home/ec2-user/intern_python/venv/lib64/python3.9/site-packages/django/middleware/common.py", line 48, in process_request
    host = request.get_host()
  File "/home/ec2-user/intern_python/venv/lib64/python3.9/site-packages/django/http/request.py", line 150, in get_host
    raise DisallowedHost(msg)
django.core.exceptions.DisallowedHost: Invalid HTTP_HOST header: '13.203.155.208'. You may need to add '13.203.155.208' to ALLOWED_HOSTS.
[2025-06-14 07:14:14 +0000] [27857] [INFO] Parent changed, shutting down: <Worker 27857>
[2025-06-14 07:14:14 +0000] [27857] [INFO] Worker exiting (pid: 27857)
[2025-06-14 07:15:00 +0000] [27941] [INFO] Starting gunicorn 23.0.0
[2025-06-14 07:15:00 +0000] [27941] [INFO] Listening at: http://0.0.0.0:8000 (27941)
[2025-06-14 07:15:00 +0000] [27941] [INFO] Using worker: sync
[2025-06-14 07:15:00 +0000] [27942] [INFO] Booting worker with pid: 27942
Not Found: /swagger
Not Found: /favicon.ico
Not Found: /swagger
[2025-06-14 07:16:20 +0000] [27942] [INFO] Parent changed, shutting down: <Worker 27942>
[2025-06-14 07:16:20 +0000] [27942] [INFO] Worker exiting (pid: 27942)
[2025-06-14 07:17:15 +0000] [28061] [INFO] Starting gunicorn 23.0.0
[2025-06-14 07:17:15 +0000] [28061] [INFO] Listening at: http://0.0.0.0:8000 (28061)
[2025-06-14 07:17:15 +0000] [28061] [INFO] Using worker: sync
[2025-06-14 07:17:15 +0000] [28062] [INFO] Booting worker with pid: 28062
[2025-06-14 07:17:20 +0000] [28062] [ERROR] Error handling request /swagger
Traceback (most recent call last):
  File "/home/ec2-user/intern_python/venv/lib64/python3.9/site-packages/django/utils/module_loading.py", line 30, in import_string
    return cached_import(module_path, class_name)
  File "/home/ec2-user/intern_python/venv/lib64/python3.9/site-packages/django/utils/module_loading.py", line 16, in cached_import
    return getattr(module, class_name)
AttributeError: partially initialized module 'drf_spectacular.views' has no attribute 'SpectacularAPIView' (most likely due to a circular import)

The above exception was the direct cause of the following exception:

Traceback (most recent call last):
  File "/home/ec2-user/intern_python/venv/lib64/python3.9/site-packages/rest_framework/settings.py", line 179, in import_from_string
    return import_string(val)
  File "/home/ec2-user/intern_python/venv/lib64/python3.9/site-packages/django/utils/module_loading.py", line 32, in import_string
    raise ImportError(
ImportError: Module "drf_spectacular.views" does not define a "SpectacularAPIView" attribute/class

During handling of the above exception, another exception occurred:

Traceback (most recent call last):
  File "/home/ec2-user/intern_python/venv/lib64/python3.9/site-packages/django/core/handlers/exception.py", line 55, in inner
    response = get_response(request)
  File "/home/ec2-user/intern_python/venv/lib64/python3.9/site-packages/django/core/handlers/base.py", line 181, in _get_response
    callback, callback_args, callback_kwargs = self.resolve_request(request)
  File "/home/ec2-user/intern_python/venv/lib64/python3.9/site-packages/django/core/handlers/base.py", line 313, in resolve_request
    resolver_match = resolver.resolve(request.path_info)
  File "/home/ec2-user/intern_python/venv/lib64/python3.9/site-packages/django/urls/resolvers.py", line 663, in resolve
    for pattern in self.url_patterns:
  File "/home/ec2-user/intern_python/venv/lib64/python3.9/site-packages/django/utils/functional.py", line 57, in __get__
    res = instance.__dict__[self.name] = self.func(instance)
  File "/home/ec2-user/intern_python/venv/lib64/python3.9/site-packages/django/urls/resolvers.py", line 715, in url_patterns
    patterns = getattr(self.urlconf_module, "urlpatterns", self.urlconf_module)
  File "/home/ec2-user/intern_python/venv/lib64/python3.9/site-packages/django/utils/functional.py", line 57, in __get__
    res = instance.__dict__[self.name] = self.func(instance)
  File "/home/ec2-user/intern_python/venv/lib64/python3.9/site-packages/django/urls/resolvers.py", line 708, in urlconf_module
    return import_module(self.urlconf_name)
  File "/usr/lib64/python3.9/importlib/__init__.py", line 127, in import_module
    return _bootstrap._gcd_import(name[level:], package, level)
  File "<frozen importlib._bootstrap>", line 1030, in _gcd_import
  File "<frozen importlib._bootstrap>", line 1007, in _find_and_load
  File "<frozen importlib._bootstrap>", line 986, in _find_and_load_unlocked
  File "<frozen importlib._bootstrap>", line 680, in _load_unlocked
  File "<frozen importlib._bootstrap_external>", line 850, in exec_module
  File "<frozen importlib._bootstrap>", line 228, in _call_with_frames_removed
  File "/home/ec2-user/intern_python/python/urls.py", line 4, in <module>
    from drf_spectacular.views import SpectacularAPIView, SpectacularSwaggerView
  File "/home/ec2-user/intern_python/venv/lib64/python3.9/site-packages/drf_spectacular/views.py", line 44, in <module>
    class SpectacularAPIView(APIView):
  File "/home/ec2-user/intern_python/venv/lib64/python3.9/site-packages/drf_spectacular/views.py", line 64, in SpectacularAPIView
    def get(self, request, *args, **kwargs):
  File "/home/ec2-user/intern_python/venv/lib64/python3.9/site-packages/drf_spectacular/utils.py", line 430, in decorator
    or api_settings.DEFAULT_SCHEMA_CLASS
  File "/home/ec2-user/intern_python/venv/lib64/python3.9/site-packages/rest_framework/settings.py", line 227, in __getattr__
    val = perform_import(val, attr)
  File "/home/ec2-user/intern_python/venv/lib64/python3.9/site-packages/rest_framework/settings.py", line 168, in perform_import
    return import_from_string(val, setting_name)
  File "/home/ec2-user/intern_python/venv/lib64/python3.9/site-packages/rest_framework/settings.py", line 182, in import_from_string
    raise ImportError(msg)
ImportError: Could not import 'drf_spectacular.views.SpectacularAPIView' for API setting 'DEFAULT_SCHEMA_CLASS'. ImportError: Module "drf_spectacular.views" does not define a "SpectacularAPIView" attribute/class.

During handling of the above exception, another exception occurred:

Traceback (most recent call last):
  File "/home/ec2-user/intern_python/venv/lib64/python3.9/site-packages/django/utils/module_loading.py", line 30, in import_string
    return cached_import(module_path, class_name)
  File "/home/ec2-user/intern_python/venv/lib64/python3.9/site-packages/django/utils/module_loading.py", line 16, in cached_import
    return getattr(module, class_name)
AttributeError: partially initialized module 'drf_spectacular.views' has no attribute 'SpectacularAPIView' (most likely due to a circular import)

The above exception was the direct cause of the following exception:

Traceback (most recent call last):
  File "/home/ec2-user/intern_python/venv/lib64/python3.9/site-packages/rest_framework/settings.py", line 179, in import_from_string
    return import_string(val)
  File "/home/ec2-user/intern_python/venv/lib64/python3.9/site-packages/django/utils/module_loading.py", line 32, in import_string
    raise ImportError(
ImportError: Module "drf_spectacular.views" does not define a "SpectacularAPIView" attribute/class

During handling of the above exception, another exception occurred:

Traceback (most recent call last):
  File "/home/ec2-user/intern_python/venv/lib64/python3.9/site-packages/django/core/handlers/exception.py", line 55, in inner
    response = get_response(request)
  File "/home/ec2-user/intern_python/venv/lib64/python3.9/site-packages/django/utils/deprecation.py", line 134, in __call__
    response = response or self.get_response(request)
  File "/home/ec2-user/intern_python/venv/lib64/python3.9/site-packages/django/core/handlers/exception.py", line 57, in inner
    response = response_for_exception(request, exc)
  File "/home/ec2-user/intern_python/venv/lib64/python3.9/site-packages/django/core/handlers/exception.py", line 141, in response_for_exception
    response = handle_uncaught_exception(
  File "/home/ec2-user/intern_python/venv/lib64/python3.9/site-packages/django/core/handlers/exception.py", line 182, in handle_uncaught_exception
    return debug.technical_500_response(request, *exc_info)
  File "/home/ec2-user/intern_python/venv/lib64/python3.9/site-packages/django/views/debug.py", line 67, in technical_500_response
    html = reporter.get_traceback_html()
  File "/home/ec2-user/intern_python/venv/lib64/python3.9/site-packages/django/views/debug.py", line 410, in get_traceback_html
    c = Context(self.get_traceback_data(), use_l10n=False)
  File "/home/ec2-user/intern_python/venv/lib64/python3.9/site-packages/django/views/debug.py", line 393, in get_traceback_data
    c["raising_view_name"] = get_caller(self.request)
  File "/home/ec2-user/intern_python/venv/lib64/python3.9/site-packages/django/views/debug.py", line 100, in get_caller
    resolver_match = resolve(request.path)
  File "/home/ec2-user/intern_python/venv/lib64/python3.9/site-packages/django/urls/base.py", line 24, in resolve
    return get_resolver(urlconf).resolve(path)
  File "/home/ec2-user/intern_python/venv/lib64/python3.9/site-packages/django/urls/resolvers.py", line 663, in resolve
    for pattern in self.url_patterns:
  File "/home/ec2-user/intern_python/venv/lib64/python3.9/site-packages/django/utils/functional.py", line 57, in __get__
    res = instance.__dict__[self.name] = self.func(instance)
  File "/home/ec2-user/intern_python/venv/lib64/python3.9/site-packages/django/urls/resolvers.py", line 715, in url_patterns
    patterns = getattr(self.urlconf_module, "urlpatterns", self.urlconf_module)
  File "/home/ec2-user/intern_python/venv/lib64/python3.9/site-packages/django/utils/functional.py", line 57, in __get__
    res = instance.__dict__[self.name] = self.func(instance)
  File "/home/ec2-user/intern_python/venv/lib64/python3.9/site-packages/django/urls/resolvers.py", line 708, in urlconf_module
    return import_module(self.urlconf_name)
  File "/usr/lib64/python3.9/importlib/__init__.py", line 127, in import_module
    return _bootstrap._gcd_import(name[level:], package, level)
  File "<frozen importlib._bootstrap>", line 1030, in _gcd_import
  File "<frozen importlib._bootstrap>", line 1007, in _find_and_load
  File "<frozen importlib._bootstrap>", line 986, in _find_and_load_unlocked
  File "<frozen importlib._bootstrap>", line 680, in _load_unlocked
  File "<frozen importlib._bootstrap_external>", line 850, in exec_module
  File "<frozen importlib._bootstrap>", line 228, in _call_with_frames_removed
  File "/home/ec2-user/intern_python/python/urls.py", line 4, in <module>
    from drf_spectacular.views import SpectacularAPIView, SpectacularSwaggerView
  File "/home/ec2-user/intern_python/venv/lib64/python3.9/site-packages/drf_spectacular/views.py", line 44, in <module>
    class SpectacularAPIView(APIView):
  File "/home/ec2-user/intern_python/venv/lib64/python3.9/site-packages/drf_spectacular/views.py", line 64, in SpectacularAPIView
    def get(self, request, *args, **kwargs):
  File "/home/ec2-user/intern_python/venv/lib64/python3.9/site-packages/drf_spectacular/utils.py", line 430, in decorator
    or api_settings.DEFAULT_SCHEMA_CLASS
  File "/home/ec2-user/intern_python/venv/lib64/python3.9/site-packages/rest_framework/settings.py", line 227, in __getattr__
    val = perform_import(val, attr)
  File "/home/ec2-user/intern_python/venv/lib64/python3.9/site-packages/rest_framework/settings.py", line 168, in perform_import
    return import_from_string(val, setting_name)
  File "/home/ec2-user/intern_python/venv/lib64/python3.9/site-packages/rest_framework/settings.py", line 182, in import_from_string
    raise ImportError(msg)
ImportError: Could not import 'drf_spectacular.views.SpectacularAPIView' for API setting 'DEFAULT_SCHEMA_CLASS'. ImportError: Module "drf_spectacular.views" does not define a "SpectacularAPIView" attribute/class.

During handling of the above exception, another exception occurred:

Traceback (most recent call last):
  File "/home/ec2-user/intern_python/venv/lib64/python3.9/site-packages/django/utils/module_loading.py", line 30, in import_string
    return cached_import(module_path, class_name)
  File "/home/ec2-user/intern_python/venv/lib64/python3.9/site-packages/django/utils/module_loading.py", line 16, in cached_import
    return getattr(module, class_name)
AttributeError: partially initialized module 'drf_spectacular.views' has no attribute 'SpectacularAPIView' (most likely due to a circular import)

The above exception was the direct cause of the following exception:

Traceback (most recent call last):
  File "/home/ec2-user/intern_python/venv/lib64/python3.9/site-packages/rest_framework/settings.py", line 179, in import_from_string
    return import_string(val)
  File "/home/ec2-user/intern_python/venv/lib64/python3.9/site-packages/django/utils/module_loading.py", line 32, in import_string
    raise ImportError(
ImportError: Module "drf_spectacular.views" does not define a "SpectacularAPIView" attribute/class

During handling of the above exception, another exception occurred:

Traceback (most recent call last):
  File "/home/ec2-user/intern_python/venv/lib64/python3.9/site-packages/django/core/handlers/exception.py", line 55, in inner
    response = get_response(request)
  File "/home/ec2-user/intern_python/venv/lib64/python3.9/site-packages/django/utils/deprecation.py", line 134, in __call__
    response = response or self.get_response(request)
  File "/home/ec2-user/intern_python/venv/lib64/python3.9/site-packages/django/core/handlers/exception.py", line 57, in inner
    response = response_for_exception(request, exc)
  File "/home/ec2-user/intern_python/venv/lib64/python3.9/site-packages/django/core/handlers/exception.py", line 141, in response_for_exception
    response = handle_uncaught_exception(
  File "/home/ec2-user/intern_python/venv/lib64/python3.9/site-packages/django/core/handlers/exception.py", line 182, in handle_uncaught_exception
    return debug.technical_500_response(request, *exc_info)
  File "/home/ec2-user/intern_python/venv/lib64/python3.9/site-packages/django/views/debug.py", line 67, in technical_500_response
    html = reporter.get_traceback_html()
  File "/home/ec2-user/intern_python/venv/lib64/python3.9/site-packages/django/views/debug.py", line 410, in get_traceback_html
    c = Context(self.get_traceback_data(), use_l10n=False)
  File "/home/ec2-user/intern_python/venv/lib64/python3.9/site-packages/django/views/debug.py", line 393, in get_traceback_data
    c["raising_view_name"] = get_caller(self.request)
  File "/home/ec2-user/intern_python/venv/lib64/python3.9/site-packages/django/views/debug.py", line 100, in get_caller
    resolver_match = resolve(request.path)
  File "/home/ec2-user/intern_python/venv/lib64/python3.9/site-packages/django/urls/base.py", line 24, in resolve
    return get_resolver(urlconf).resolve(path)
  File "/home/ec2-user/intern_python/venv/lib64/python3.9/site-packages/django/urls/resolvers.py", line 663, in resolve
    for pattern in self.url_patterns:
  File "/home/ec2-user/intern_python/venv/lib64/python3.9/site-packages/django/utils/functional.py", line 57, in __get__
    res = instance.__dict__[self.name] = self.func(instance)
  File "/home/ec2-user/intern_python/venv/lib64/python3.9/site-packages/django/urls/resolvers.py", line 715, in url_patterns
    patterns = getattr(self.urlconf_module, "urlpatterns", self.urlconf_module)
  File "/home/ec2-user/intern_python/venv/lib64/python3.9/site-packages/django/utils/functional.py", line 57, in __get__
    res = instance.__dict__[self.name] = self.func(instance)
  File "/home/ec2-user/intern_python/venv/lib64/python3.9/site-packages/django/urls/resolvers.py", line 708, in urlconf_module
    return import_module(self.urlconf_name)
  File "/usr/lib64/python3.9/importlib/__init__.py", line 127, in import_module
    return _bootstrap._gcd_import(name[level:], package, level)
  File "<frozen importlib._bootstrap>", line 1030, in _gcd_import
  File "<frozen importlib._bootstrap>", line 1007, in _find_and_load
  File "<frozen importlib._bootstrap>", line 986, in _find_and_load_unlocked
  File "<frozen importlib._bootstrap>", line 680, in _load_unlocked
  File "<frozen importlib._bootstrap_external>", line 850, in exec_module
  File "<frozen importlib._bootstrap>", line 228, in _call_with_frames_removed
  File "/home/ec2-user/intern_python/python/urls.py", line 4, in <module>
    from drf_spectacular.views import SpectacularAPIView, SpectacularSwaggerView
  File "/home/ec2-user/intern_python/venv/lib64/python3.9/site-packages/drf_spectacular/views.py", line 44, in <module>
    class SpectacularAPIView(APIView):
  File "/home/ec2-user/intern_python/venv/lib64/python3.9/site-packages/drf_spectacular/views.py", line 64, in SpectacularAPIView
    def get(self, request, *args, **kwargs):
  File "/home/ec2-user/intern_python/venv/lib64/python3.9/site-packages/drf_spectacular/utils.py", line 430, in decorator
    or api_settings.DEFAULT_SCHEMA_CLASS
  File "/home/ec2-user/intern_python/venv/lib64/python3.9/site-packages/rest_framework/settings.py", line 227, in __getattr__
    val = perform_import(val, attr)
  File "/home/ec2-user/intern_python/venv/lib64/python3.9/site-packages/rest_framework/settings.py", line 168, in perform_import
    return import_from_string(val, setting_name)
  File "/home/ec2-user/intern_python/venv/lib64/python3.9/site-packages/rest_framework/settings.py", line 182, in import_from_string
    raise ImportError(msg)
ImportError: Could not import 'drf_spectacular.views.SpectacularAPIView' for API setting 'DEFAULT_SCHEMA_CLASS'. ImportError: Module "drf_spectacular.views" does not define a "SpectacularAPIView" attribute/class.

During handling of the above exception, another exception occurred:

Traceback (most recent call last):
  File "/home/ec2-user/intern_python/venv/lib64/python3.9/site-packages/django/utils/module_loading.py", line 30, in import_string
    return cached_import(module_path, class_name)
  File "/home/ec2-user/intern_python/venv/lib64/python3.9/site-packages/django/utils/module_loading.py", line 16, in cached_import
    return getattr(module, class_name)
AttributeError: partially initialized module 'drf_spectacular.views' has no attribute 'SpectacularAPIView' (most likely due to a circular import)

The above exception was the direct cause of the following exception:

Traceback (most recent call last):
  File "/home/ec2-user/intern_python/venv/lib64/python3.9/site-packages/rest_framework/settings.py", line 179, in import_from_string
    return import_string(val)
  File "/home/ec2-user/intern_python/venv/lib64/python3.9/site-packages/django/utils/module_loading.py", line 32, in import_string
    raise ImportError(
ImportError: Module "drf_spectacular.views" does not define a "SpectacularAPIView" attribute/class

During handling of the above exception, another exception occurred:

Traceback (most recent call last):
  File "/home/ec2-user/intern_python/venv/lib64/python3.9/site-packages/django/core/handlers/exception.py", line 55, in inner
    response = get_response(request)
  File "/home/ec2-user/intern_python/venv/lib64/python3.9/site-packages/django/utils/deprecation.py", line 134, in __call__
    response = response or self.get_response(request)
  File "/home/ec2-user/intern_python/venv/lib64/python3.9/site-packages/django/core/handlers/exception.py", line 57, in inner
    response = response_for_exception(request, exc)
  File "/home/ec2-user/intern_python/venv/lib64/python3.9/site-packages/django/core/handlers/exception.py", line 141, in response_for_exception
    response = handle_uncaught_exception(
  File "/home/ec2-user/intern_python/venv/lib64/python3.9/site-packages/django/core/handlers/exception.py", line 182, in handle_uncaught_exception
    return debug.technical_500_response(request, *exc_info)
  File "/home/ec2-user/intern_python/venv/lib64/python3.9/site-packages/django/views/debug.py", line 67, in technical_500_response
    html = reporter.get_traceback_html()
  File "/home/ec2-user/intern_python/venv/lib64/python3.9/site-packages/django/views/debug.py", line 410, in get_traceback_html
    c = Context(self.get_traceback_data(), use_l10n=False)
  File "/home/ec2-user/intern_python/venv/lib64/python3.9/site-packages/django/views/debug.py", line 393, in get_traceback_data
    c["raising_view_name"] = get_caller(self.request)
  File "/home/ec2-user/intern_python/venv/lib64/python3.9/site-packages/django/views/debug.py", line 100, in get_caller
    resolver_match = resolve(request.path)
  File "/home/ec2-user/intern_python/venv/lib64/python3.9/site-packages/django/urls/base.py", line 24, in resolve
    return get_resolver(urlconf).resolve(path)
  File "/home/ec2-user/intern_python/venv/lib64/python3.9/site-packages/django/urls/resolvers.py", line 663, in resolve
    for pattern in self.url_patterns:
  File "/home/ec2-user/intern_python/venv/lib64/python3.9/site-packages/django/utils/functional.py", line 57, in __get__
    res = instance.__dict__[self.name] = self.func(instance)
  File "/home/ec2-user/intern_python/venv/lib64/python3.9/site-packages/django/urls/resolvers.py", line 715, in url_patterns
    patterns = getattr(self.urlconf_module, "urlpatterns", self.urlconf_module)
  File "/home/ec2-user/intern_python/venv/lib64/python3.9/site-packages/django/utils/functional.py", line 57, in __get__
    res = instance.__dict__[self.name] = self.func(instance)
  File "/home/ec2-user/intern_python/venv/lib64/python3.9/site-packages/django/urls/resolvers.py", line 708, in urlconf_module
    return import_module(self.urlconf_name)
  File "/usr/lib64/python3.9/importlib/__init__.py", line 127, in import_module
    return _bootstrap._gcd_import(name[level:], package, level)
  File "<frozen importlib._bootstrap>", line 1030, in _gcd_import
  File "<frozen importlib._bootstrap>", line 1007, in _find_and_load
  File "<frozen importlib._bootstrap>", line 986, in _find_and_load_unlocked
  File "<frozen importlib._bootstrap>", line 680, in _load_unlocked
  File "<frozen importlib._bootstrap_external>", line 850, in exec_module
  File "<frozen importlib._bootstrap>", line 228, in _call_with_frames_removed
  File "/home/ec2-user/intern_python/python/urls.py", line 4, in <module>
    from drf_spectacular.views import SpectacularAPIView, SpectacularSwaggerView
  File "/home/ec2-user/intern_python/venv/lib64/python3.9/site-packages/drf_spectacular/views.py", line 44, in <module>
    class SpectacularAPIView(APIView):
  File "/home/ec2-user/intern_python/venv/lib64/python3.9/site-packages/drf_spectacular/views.py", line 64, in SpectacularAPIView
    def get(self, request, *args, **kwargs):
  File "/home/ec2-user/intern_python/venv/lib64/python3.9/site-packages/drf_spectacular/utils.py", line 430, in decorator
    or api_settings.DEFAULT_SCHEMA_CLASS
  File "/home/ec2-user/intern_python/venv/lib64/python3.9/site-packages/rest_framework/settings.py", line 227, in __getattr__
    val = perform_import(val, attr)
  File "/home/ec2-user/intern_python/venv/lib64/python3.9/site-packages/rest_framework/settings.py", line 168, in perform_import
    return import_from_string(val, setting_name)
  File "/home/ec2-user/intern_python/venv/lib64/python3.9/site-packages/rest_framework/settings.py", line 182, in import_from_string
    raise ImportError(msg)
ImportError: Could not import 'drf_spectacular.views.SpectacularAPIView' for API setting 'DEFAULT_SCHEMA_CLASS'. ImportError: Module "drf_spectacular.views" does not define a "SpectacularAPIView" attribute/class.

During handling of the above exception, another exception occurred:

Traceback (most recent call last):
  File "/home/ec2-user/intern_python/venv/lib64/python3.9/site-packages/django/utils/module_loading.py", line 30, in import_string
    return cached_import(module_path, class_name)
  File "/home/ec2-user/intern_python/venv/lib64/python3.9/site-packages/django/utils/module_loading.py", line 16, in cached_import
    return getattr(module, class_name)
AttributeError: partially initialized module 'drf_spectacular.views' has no attribute 'SpectacularAPIView' (most likely due to a circular import)

The above exception was the direct cause of the following exception:

Traceback (most recent call last):
  File "/home/ec2-user/intern_python/venv/lib64/python3.9/site-packages/rest_framework/settings.py", line 179, in import_from_string
    return import_string(val)
  File "/home/ec2-user/intern_python/venv/lib64/python3.9/site-packages/django/utils/module_loading.py", line 32, in import_string
    raise ImportError(
ImportError: Module "drf_spectacular.views" does not define a "SpectacularAPIView" attribute/class

During handling of the above exception, another exception occurred:

Traceback (most recent call last):
  File "/home/ec2-user/intern_python/venv/lib64/python3.9/site-packages/django/core/handlers/exception.py", line 55, in inner
    response = get_response(request)
  File "/home/ec2-user/intern_python/venv/lib64/python3.9/site-packages/django/utils/deprecation.py", line 134, in __call__
    response = response or self.get_response(request)
  File "/home/ec2-user/intern_python/venv/lib64/python3.9/site-packages/django/core/handlers/exception.py", line 57, in inner
    response = response_for_exception(request, exc)
  File "/home/ec2-user/intern_python/venv/lib64/python3.9/site-packages/django/core/handlers/exception.py", line 141, in response_for_exception
    response = handle_uncaught_exception(
  File "/home/ec2-user/intern_python/venv/lib64/python3.9/site-packages/django/core/handlers/exception.py", line 182, in handle_uncaught_exception
    return debug.technical_500_response(request, *exc_info)
  File "/home/ec2-user/intern_python/venv/lib64/python3.9/site-packages/django/views/debug.py", line 67, in technical_500_response
    html = reporter.get_traceback_html()
  File "/home/ec2-user/intern_python/venv/lib64/python3.9/site-packages/django/views/debug.py", line 410, in get_traceback_html
    c = Context(self.get_traceback_data(), use_l10n=False)
  File "/home/ec2-user/intern_python/venv/lib64/python3.9/site-packages/django/views/debug.py", line 393, in get_traceback_data
    c["raising_view_name"] = get_caller(self.request)
  File "/home/ec2-user/intern_python/venv/lib64/python3.9/site-packages/django/views/debug.py", line 100, in get_caller
    resolver_match = resolve(request.path)
  File "/home/ec2-user/intern_python/venv/lib64/python3.9/site-packages/django/urls/base.py", line 24, in resolve
    return get_resolver(urlconf).resolve(path)
  File "/home/ec2-user/intern_python/venv/lib64/python3.9/site-packages/django/urls/resolvers.py", line 663, in resolve
    for pattern in self.url_patterns:
  File "/home/ec2-user/intern_python/venv/lib64/python3.9/site-packages/django/utils/functional.py", line 57, in __get__
    res = instance.__dict__[self.name] = self.func(instance)
  File "/home/ec2-user/intern_python/venv/lib64/python3.9/site-packages/django/urls/resolvers.py", line 715, in url_patterns
    patterns = getattr(self.urlconf_module, "urlpatterns", self.urlconf_module)
  File "/home/ec2-user/intern_python/venv/lib64/python3.9/site-packages/django/utils/functional.py", line 57, in __get__
    res = instance.__dict__[self.name] = self.func(instance)
  File "/home/ec2-user/intern_python/venv/lib64/python3.9/site-packages/django/urls/resolvers.py", line 708, in urlconf_module
    return import_module(self.urlconf_name)
  File "/usr/lib64/python3.9/importlib/__init__.py", line 127, in import_module
    return _bootstrap._gcd_import(name[level:], package, level)
  File "<frozen importlib._bootstrap>", line 1030, in _gcd_import
  File "<frozen importlib._bootstrap>", line 1007, in _find_and_load
  File "<frozen importlib._bootstrap>", line 986, in _find_and_load_unlocked
  File "<frozen importlib._bootstrap>", line 680, in _load_unlocked
  File "<frozen importlib._bootstrap_external>", line 850, in exec_module
  File "<frozen importlib._bootstrap>", line 228, in _call_with_frames_removed
  File "/home/ec2-user/intern_python/python/urls.py", line 4, in <module>
    from drf_spectacular.views import SpectacularAPIView, SpectacularSwaggerView
  File "/home/ec2-user/intern_python/venv/lib64/python3.9/site-packages/drf_spectacular/views.py", line 44, in <module>
    class SpectacularAPIView(APIView):
  File "/home/ec2-user/intern_python/venv/lib64/python3.9/site-packages/drf_spectacular/views.py", line 64, in SpectacularAPIView
    def get(self, request, *args, **kwargs):
  File "/home/ec2-user/intern_python/venv/lib64/python3.9/site-packages/drf_spectacular/utils.py", line 430, in decorator
    or api_settings.DEFAULT_SCHEMA_CLASS
  File "/home/ec2-user/intern_python/venv/lib64/python3.9/site-packages/rest_framework/settings.py", line 227, in __getattr__
    val = perform_import(val, attr)
  File "/home/ec2-user/intern_python/venv/lib64/python3.9/site-packages/rest_framework/settings.py", line 168, in perform_import
    return import_from_string(val, setting_name)
  File "/home/ec2-user/intern_python/venv/lib64/python3.9/site-packages/rest_framework/settings.py", line 182, in import_from_string
    raise ImportError(msg)
ImportError: Could not import 'drf_spectacular.views.SpectacularAPIView' for API setting 'DEFAULT_SCHEMA_CLASS'. ImportError: Module "drf_spectacular.views" does not define a "SpectacularAPIView" attribute/class.

During handling of the above exception, another exception occurred:

Traceback (most recent call last):
  File "/home/ec2-user/intern_python/venv/lib64/python3.9/site-packages/django/utils/module_loading.py", line 30, in import_string
    return cached_import(module_path, class_name)
  File "/home/ec2-user/intern_python/venv/lib64/python3.9/site-packages/django/utils/module_loading.py", line 16, in cached_import
    return getattr(module, class_name)
AttributeError: partially initialized module 'drf_spectacular.views' has no attribute 'SpectacularAPIView' (most likely due to a circular import)

The above exception was the direct cause of the following exception:

Traceback (most recent call last):
  File "/home/ec2-user/intern_python/venv/lib64/python3.9/site-packages/rest_framework/settings.py", line 179, in import_from_string
    return import_string(val)
  File "/home/ec2-user/intern_python/venv/lib64/python3.9/site-packages/django/utils/module_loading.py", line 32, in import_string
    raise ImportError(
ImportError: Module "drf_spectacular.views" does not define a "SpectacularAPIView" attribute/class

During handling of the above exception, another exception occurred:

Traceback (most recent call last):
  File "/home/ec2-user/intern_python/venv/lib64/python3.9/site-packages/django/core/handlers/exception.py", line 55, in inner
    response = get_response(request)
  File "/home/ec2-user/intern_python/venv/lib64/python3.9/site-packages/django/utils/deprecation.py", line 134, in __call__
    response = response or self.get_response(request)
  File "/home/ec2-user/intern_python/venv/lib64/python3.9/site-packages/django/core/handlers/exception.py", line 57, in inner
    response = response_for_exception(request, exc)
  File "/home/ec2-user/intern_python/venv/lib64/python3.9/site-packages/django/core/handlers/exception.py", line 141, in response_for_exception
    response = handle_uncaught_exception(
  File "/home/ec2-user/intern_python/venv/lib64/python3.9/site-packages/django/core/handlers/exception.py", line 182, in handle_uncaught_exception
    return debug.technical_500_response(request, *exc_info)
  File "/home/ec2-user/intern_python/venv/lib64/python3.9/site-packages/django/views/debug.py", line 67, in technical_500_response
    html = reporter.get_traceback_html()
  File "/home/ec2-user/intern_python/venv/lib64/python3.9/site-packages/django/views/debug.py", line 410, in get_traceback_html
    c = Context(self.get_traceback_data(), use_l10n=False)
  File "/home/ec2-user/intern_python/venv/lib64/python3.9/site-packages/django/views/debug.py", line 393, in get_traceback_data
    c["raising_view_name"] = get_caller(self.request)
  File "/home/ec2-user/intern_python/venv/lib64/python3.9/site-packages/django/views/debug.py", line 100, in get_caller
    resolver_match = resolve(request.path)
  File "/home/ec2-user/intern_python/venv/lib64/python3.9/site-packages/django/urls/base.py", line 24, in resolve
    return get_resolver(urlconf).resolve(path)
  File "/home/ec2-user/intern_python/venv/lib64/python3.9/site-packages/django/urls/resolvers.py", line 663, in resolve
    for pattern in self.url_patterns:
  File "/home/ec2-user/intern_python/venv/lib64/python3.9/site-packages/django/utils/functional.py", line 57, in __get__
    res = instance.__dict__[self.name] = self.func(instance)
  File "/home/ec2-user/intern_python/venv/lib64/python3.9/site-packages/django/urls/resolvers.py", line 715, in url_patterns
    patterns = getattr(self.urlconf_module, "urlpatterns", self.urlconf_module)
  File "/home/ec2-user/intern_python/venv/lib64/python3.9/site-packages/django/utils/functional.py", line 57, in __get__
    res = instance.__dict__[self.name] = self.func(instance)
  File "/home/ec2-user/intern_python/venv/lib64/python3.9/site-packages/django/urls/resolvers.py", line 708, in urlconf_module
    return import_module(self.urlconf_name)
  File "/usr/lib64/python3.9/importlib/__init__.py", line 127, in import_module
    return _bootstrap._gcd_import(name[level:], package, level)
  File "<frozen importlib._bootstrap>", line 1030, in _gcd_import
  File "<frozen importlib._bootstrap>", line 1007, in _find_and_load
  File "<frozen importlib._bootstrap>", line 986, in _find_and_load_unlocked
  File "<frozen importlib._bootstrap>", line 680, in _load_unlocked
  File "<frozen importlib._bootstrap_external>", line 850, in exec_module
  File "<frozen importlib._bootstrap>", line 228, in _call_with_frames_removed
  File "/home/ec2-user/intern_python/python/urls.py", line 4, in <module>
    from drf_spectacular.views import SpectacularAPIView, SpectacularSwaggerView
  File "/home/ec2-user/intern_python/venv/lib64/python3.9/site-packages/drf_spectacular/views.py", line 44, in <module>
    class SpectacularAPIView(APIView):
  File "/home/ec2-user/intern_python/venv/lib64/python3.9/site-packages/drf_spectacular/views.py", line 64, in SpectacularAPIView
    def get(self, request, *args, **kwargs):
  File "/home/ec2-user/intern_python/venv/lib64/python3.9/site-packages/drf_spectacular/utils.py", line 430, in decorator
    or api_settings.DEFAULT_SCHEMA_CLASS
  File "/home/ec2-user/intern_python/venv/lib64/python3.9/site-packages/rest_framework/settings.py", line 227, in __getattr__
    val = perform_import(val, attr)
  File "/home/ec2-user/intern_python/venv/lib64/python3.9/site-packages/rest_framework/settings.py", line 168, in perform_import
    return import_from_string(val, setting_name)
  File "/home/ec2-user/intern_python/venv/lib64/python3.9/site-packages/rest_framework/settings.py", line 182, in import_from_string
    raise ImportError(msg)
ImportError: Could not import 'drf_spectacular.views.SpectacularAPIView' for API setting 'DEFAULT_SCHEMA_CLASS'. ImportError: Module "drf_spectacular.views" does not define a "SpectacularAPIView" attribute/class.

During handling of the above exception, another exception occurred:

Traceback (most recent call last):
  File "/home/ec2-user/intern_python/venv/lib64/python3.9/site-packages/django/utils/module_loading.py", line 30, in import_string
    return cached_import(module_path, class_name)
  File "/home/ec2-user/intern_python/venv/lib64/python3.9/site-packages/django/utils/module_loading.py", line 16, in cached_import
    return getattr(module, class_name)
AttributeError: partially initialized module 'drf_spectacular.views' has no attribute 'SpectacularAPIView' (most likely due to a circular import)

The above exception was the direct cause of the following exception:

Traceback (most recent call last):
  File "/home/ec2-user/intern_python/venv/lib64/python3.9/site-packages/rest_framework/settings.py", line 179, in import_from_string
    return import_string(val)
  File "/home/ec2-user/intern_python/venv/lib64/python3.9/site-packages/django/utils/module_loading.py", line 32, in import_string
    raise ImportError(
ImportError: Module "drf_spectacular.views" does not define a "SpectacularAPIView" attribute/class

During handling of the above exception, another exception occurred:

Traceback (most recent call last):
  File "/home/ec2-user/intern_python/venv/lib64/python3.9/site-packages/django/core/handlers/exception.py", line 55, in inner
    response = get_response(request)
  File "/home/ec2-user/intern_python/venv/lib64/python3.9/site-packages/django/utils/deprecation.py", line 134, in __call__
    response = response or self.get_response(request)
  File "/home/ec2-user/intern_python/venv/lib64/python3.9/site-packages/django/core/handlers/exception.py", line 57, in inner
    response = response_for_exception(request, exc)
  File "/home/ec2-user/intern_python/venv/lib64/python3.9/site-packages/django/core/handlers/exception.py", line 141, in response_for_exception
    response = handle_uncaught_exception(
  File "/home/ec2-user/intern_python/venv/lib64/python3.9/site-packages/django/core/handlers/exception.py", line 182, in handle_uncaught_exception
    return debug.technical_500_response(request, *exc_info)
  File "/home/ec2-user/intern_python/venv/lib64/python3.9/site-packages/django/views/debug.py", line 67, in technical_500_response
    html = reporter.get_traceback_html()
  File "/home/ec2-user/intern_python/venv/lib64/python3.9/site-packages/django/views/debug.py", line 410, in get_traceback_html
    c = Context(self.get_traceback_data(), use_l10n=False)
  File "/home/ec2-user/intern_python/venv/lib64/python3.9/site-packages/django/views/debug.py", line 393, in get_traceback_data
    c["raising_view_name"] = get_caller(self.request)
  File "/home/ec2-user/intern_python/venv/lib64/python3.9/site-packages/django/views/debug.py", line 100, in get_caller
    resolver_match = resolve(request.path)
  File "/home/ec2-user/intern_python/venv/lib64/python3.9/site-packages/django/urls/base.py", line 24, in resolve
    return get_resolver(urlconf).resolve(path)
  File "/home/ec2-user/intern_python/venv/lib64/python3.9/site-packages/django/urls/resolvers.py", line 663, in resolve
    for pattern in self.url_patterns:
  File "/home/ec2-user/intern_python/venv/lib64/python3.9/site-packages/django/utils/functional.py", line 57, in __get__
    res = instance.__dict__[self.name] = self.func(instance)
  File "/home/ec2-user/intern_python/venv/lib64/python3.9/site-packages/django/urls/resolvers.py", line 715, in url_patterns
    patterns = getattr(self.urlconf_module, "urlpatterns", self.urlconf_module)
  File "/home/ec2-user/intern_python/venv/lib64/python3.9/site-packages/django/utils/functional.py", line 57, in __get__
    res = instance.__dict__[self.name] = self.func(instance)
  File "/home/ec2-user/intern_python/venv/lib64/python3.9/site-packages/django/urls/resolvers.py", line 708, in urlconf_module
    return import_module(self.urlconf_name)
  File "/usr/lib64/python3.9/importlib/__init__.py", line 127, in import_module
    return _bootstrap._gcd_import(name[level:], package, level)
  File "<frozen importlib._bootstrap>", line 1030, in _gcd_import
  File "<frozen importlib._bootstrap>", line 1007, in _find_and_load
  File "<frozen importlib._bootstrap>", line 986, in _find_and_load_unlocked
  File "<frozen importlib._bootstrap>", line 680, in _load_unlocked
  File "<frozen importlib._bootstrap_external>", line 850, in exec_module
  File "<frozen importlib._bootstrap>", line 228, in _call_with_frames_removed
  File "/home/ec2-user/intern_python/python/urls.py", line 4, in <module>
    from drf_spectacular.views import SpectacularAPIView, SpectacularSwaggerView
  File "/home/ec2-user/intern_python/venv/lib64/python3.9/site-packages/drf_spectacular/views.py", line 44, in <module>
    class SpectacularAPIView(APIView):
  File "/home/ec2-user/intern_python/venv/lib64/python3.9/site-packages/drf_spectacular/views.py", line 64, in SpectacularAPIView
    def get(self, request, *args, **kwargs):
  File "/home/ec2-user/intern_python/venv/lib64/python3.9/site-packages/drf_spectacular/utils.py", line 430, in decorator
    or api_settings.DEFAULT_SCHEMA_CLASS
  File "/home/ec2-user/intern_python/venv/lib64/python3.9/site-packages/rest_framework/settings.py", line 227, in __getattr__
    val = perform_import(val, attr)
  File "/home/ec2-user/intern_python/venv/lib64/python3.9/site-packages/rest_framework/settings.py", line 168, in perform_import
    return import_from_string(val, setting_name)
  File "/home/ec2-user/intern_python/venv/lib64/python3.9/site-packages/rest_framework/settings.py", line 182, in import_from_string
    raise ImportError(msg)
ImportError: Could not import 'drf_spectacular.views.SpectacularAPIView' for API setting 'DEFAULT_SCHEMA_CLASS'. ImportError: Module "drf_spectacular.views" does not define a "SpectacularAPIView" attribute/class.

During handling of the above exception, another exception occurred:

Traceback (most recent call last):
  File "/home/ec2-user/intern_python/venv/lib64/python3.9/site-packages/django/utils/module_loading.py", line 30, in import_string
    return cached_import(module_path, class_name)
  File "/home/ec2-user/intern_python/venv/lib64/python3.9/site-packages/django/utils/module_loading.py", line 16, in cached_import
    return getattr(module, class_name)
AttributeError: partially initialized module 'drf_spectacular.views' has no attribute 'SpectacularAPIView' (most likely due to a circular import)

The above exception was the direct cause of the following exception:

Traceback (most recent call last):
  File "/home/ec2-user/intern_python/venv/lib64/python3.9/site-packages/rest_framework/settings.py", line 179, in import_from_string
    return import_string(val)
  File "/home/ec2-user/intern_python/venv/lib64/python3.9/site-packages/django/utils/module_loading.py", line 32, in import_string
    raise ImportError(
ImportError: Module "drf_spectacular.views" does not define a "SpectacularAPIView" attribute/class

During handling of the above exception, another exception occurred:

Traceback (most recent call last):
  File "/home/ec2-user/intern_python/venv/lib64/python3.9/site-packages/django/core/handlers/exception.py", line 55, in inner
    response = get_response(request)
  File "/home/ec2-user/intern_python/venv/lib64/python3.9/site-packages/django/utils/deprecation.py", line 134, in __call__
    response = response or self.get_response(request)
  File "/home/ec2-user/intern_python/venv/lib64/python3.9/site-packages/django/core/handlers/exception.py", line 57, in inner
    response = response_for_exception(request, exc)
  File "/home/ec2-user/intern_python/venv/lib64/python3.9/site-packages/django/core/handlers/exception.py", line 141, in response_for_exception
    response = handle_uncaught_exception(
  File "/home/ec2-user/intern_python/venv/lib64/python3.9/site-packages/django/core/handlers/exception.py", line 182, in handle_uncaught_exception
    return debug.technical_500_response(request, *exc_info)
  File "/home/ec2-user/intern_python/venv/lib64/python3.9/site-packages/django/views/debug.py", line 67, in technical_500_response
    html = reporter.get_traceback_html()
  File "/home/ec2-user/intern_python/venv/lib64/python3.9/site-packages/django/views/debug.py", line 410, in get_traceback_html
    c = Context(self.get_traceback_data(), use_l10n=False)
  File "/home/ec2-user/intern_python/venv/lib64/python3.9/site-packages/django/views/debug.py", line 393, in get_traceback_data
    c["raising_view_name"] = get_caller(self.request)
  File "/home/ec2-user/intern_python/venv/lib64/python3.9/site-packages/django/views/debug.py", line 100, in get_caller
    resolver_match = resolve(request.path)
  File "/home/ec2-user/intern_python/venv/lib64/python3.9/site-packages/django/urls/base.py", line 24, in resolve
    return get_resolver(urlconf).resolve(path)
  File "/home/ec2-user/intern_python/venv/lib64/python3.9/site-packages/django/urls/resolvers.py", line 663, in resolve
    for pattern in self.url_patterns:
  File "/home/ec2-user/intern_python/venv/lib64/python3.9/site-packages/django/utils/functional.py", line 57, in __get__
    res = instance.__dict__[self.name] = self.func(instance)
  File "/home/ec2-user/intern_python/venv/lib64/python3.9/site-packages/django/urls/resolvers.py", line 715, in url_patterns
    patterns = getattr(self.urlconf_module, "urlpatterns", self.urlconf_module)
  File "/home/ec2-user/intern_python/venv/lib64/python3.9/site-packages/django/utils/functional.py", line 57, in __get__
    res = instance.__dict__[self.name] = self.func(instance)
  File "/home/ec2-user/intern_python/venv/lib64/python3.9/site-packages/django/urls/resolvers.py", line 708, in urlconf_module
    return import_module(self.urlconf_name)
  File "/usr/lib64/python3.9/importlib/__init__.py", line 127, in import_module
    return _bootstrap._gcd_import(name[level:], package, level)
  File "<frozen importlib._bootstrap>", line 1030, in _gcd_import
  File "<frozen importlib._bootstrap>", line 1007, in _find_and_load
  File "<frozen importlib._bootstrap>", line 986, in _find_and_load_unlocked
  File "<frozen importlib._bootstrap>", line 680, in _load_unlocked
  File "<frozen importlib._bootstrap_external>", line 850, in exec_module
  File "<frozen importlib._bootstrap>", line 228, in _call_with_frames_removed
  File "/home/ec2-user/intern_python/python/urls.py", line 4, in <module>
    from drf_spectacular.views import SpectacularAPIView, SpectacularSwaggerView
  File "/home/ec2-user/intern_python/venv/lib64/python3.9/site-packages/drf_spectacular/views.py", line 44, in <module>
    class SpectacularAPIView(APIView):
  File "/home/ec2-user/intern_python/venv/lib64/python3.9/site-packages/drf_spectacular/views.py", line 64, in SpectacularAPIView
    def get(self, request, *args, **kwargs):
  File "/home/ec2-user/intern_python/venv/lib64/python3.9/site-packages/drf_spectacular/utils.py", line 430, in decorator
    or api_settings.DEFAULT_SCHEMA_CLASS
  File "/home/ec2-user/intern_python/venv/lib64/python3.9/site-packages/rest_framework/settings.py", line 227, in __getattr__
    val = perform_import(val, attr)
  File "/home/ec2-user/intern_python/venv/lib64/python3.9/site-packages/rest_framework/settings.py", line 168, in perform_import
    return import_from_string(val, setting_name)
  File "/home/ec2-user/intern_python/venv/lib64/python3.9/site-packages/rest_framework/settings.py", line 182, in import_from_string
    raise ImportError(msg)
ImportError: Could not import 'drf_spectacular.views.SpectacularAPIView' for API setting 'DEFAULT_SCHEMA_CLASS'. ImportError: Module "drf_spectacular.views" does not define a "SpectacularAPIView" attribute/class.

During handling of the above exception, another exception occurred:

Traceback (most recent call last):
  File "/home/ec2-user/intern_python/venv/lib64/python3.9/site-packages/django/utils/module_loading.py", line 30, in import_string
    return cached_import(module_path, class_name)
  File "/home/ec2-user/intern_python/venv/lib64/python3.9/site-packages/django/utils/module_loading.py", line 16, in cached_import
    return getattr(module, class_name)
AttributeError: partially initialized module 'drf_spectacular.views' has no attribute 'SpectacularAPIView' (most likely due to a circular import)

The above exception was the direct cause of the following exception:

Traceback (most recent call last):
  File "/home/ec2-user/intern_python/venv/lib64/python3.9/site-packages/rest_framework/settings.py", line 179, in import_from_string
    return import_string(val)
  File "/home/ec2-user/intern_python/venv/lib64/python3.9/site-packages/django/utils/module_loading.py", line 32, in import_string
    raise ImportError(
ImportError: Module "drf_spectacular.views" does not define a "SpectacularAPIView" attribute/class

During handling of the above exception, another exception occurred:

Traceback (most recent call last):
  File "/home/ec2-user/intern_python/venv/lib64/python3.9/site-packages/gunicorn/workers/sync.py", line 134, in handle
    self.handle_request(listener, req, client, addr)
  File "/home/ec2-user/intern_python/venv/lib64/python3.9/site-packages/gunicorn/workers/sync.py", line 177, in handle_request
    respiter = self.wsgi(environ, resp.start_response)
  File "/home/ec2-user/intern_python/venv/lib64/python3.9/site-packages/django/core/handlers/wsgi.py", line 124, in __call__
    response = self.get_response(request)
  File "/home/ec2-user/intern_python/venv/lib64/python3.9/site-packages/django/core/handlers/base.py", line 140, in get_response
    response = self._middleware_chain(request)
  File "/home/ec2-user/intern_python/venv/lib64/python3.9/site-packages/django/core/handlers/exception.py", line 57, in inner
    response = response_for_exception(request, exc)
  File "/home/ec2-user/intern_python/venv/lib64/python3.9/site-packages/django/core/handlers/exception.py", line 141, in response_for_exception
    response = handle_uncaught_exception(
  File "/home/ec2-user/intern_python/venv/lib64/python3.9/site-packages/django/core/handlers/exception.py", line 182, in handle_uncaught_exception
    return debug.technical_500_response(request, *exc_info)
  File "/home/ec2-user/intern_python/venv/lib64/python3.9/site-packages/django/views/debug.py", line 67, in technical_500_response
    html = reporter.get_traceback_html()
  File "/home/ec2-user/intern_python/venv/lib64/python3.9/site-packages/django/views/debug.py", line 410, in get_traceback_html
    c = Context(self.get_traceback_data(), use_l10n=False)
  File "/home/ec2-user/intern_python/venv/lib64/python3.9/site-packages/django/views/debug.py", line 393, in get_traceback_data
    c["raising_view_name"] = get_caller(self.request)
  File "/home/ec2-user/intern_python/venv/lib64/python3.9/site-packages/django/views/debug.py", line 100, in get_caller
    resolver_match = resolve(request.path)
  File "/home/ec2-user/intern_python/venv/lib64/python3.9/site-packages/django/urls/base.py", line 24, in resolve
    return get_resolver(urlconf).resolve(path)
  File "/home/ec2-user/intern_python/venv/lib64/python3.9/site-packages/django/urls/resolvers.py", line 663, in resolve
    for pattern in self.url_patterns:
  File "/home/ec2-user/intern_python/venv/lib64/python3.9/site-packages/django/utils/functional.py", line 57, in __get__
    res = instance.__dict__[self.name] = self.func(instance)
  File "/home/ec2-user/intern_python/venv/lib64/python3.9/site-packages/django/urls/resolvers.py", line 715, in url_patterns
    patterns = getattr(self.urlconf_module, "urlpatterns", self.urlconf_module)
  File "/home/ec2-user/intern_python/venv/lib64/python3.9/site-packages/django/utils/functional.py", line 57, in __get__
    res = instance.__dict__[self.name] = self.func(instance)
  File "/home/ec2-user/intern_python/venv/lib64/python3.9/site-packages/django/urls/resolvers.py", line 708, in urlconf_module
    return import_module(self.urlconf_name)
  File "/usr/lib64/python3.9/importlib/__init__.py", line 127, in import_module
    return _bootstrap._gcd_import(name[level:], package, level)
  File "<frozen importlib._bootstrap>", line 1030, in _gcd_import
  File "<frozen importlib._bootstrap>", line 1007, in _find_and_load
  File "<frozen importlib._bootstrap>", line 986, in _find_and_load_unlocked
  File "<frozen importlib._bootstrap>", line 680, in _load_unlocked
  File "<frozen importlib._bootstrap_external>", line 850, in exec_module
  File "<frozen importlib._bootstrap>", line 228, in _call_with_frames_removed
  File "/home/ec2-user/intern_python/python/urls.py", line 4, in <module>
    from drf_spectacular.views import SpectacularAPIView, SpectacularSwaggerView
  File "/home/ec2-user/intern_python/venv/lib64/python3.9/site-packages/drf_spectacular/views.py", line 44, in <module>
    class SpectacularAPIView(APIView):
  File "/home/ec2-user/intern_python/venv/lib64/python3.9/site-packages/drf_spectacular/views.py", line 64, in SpectacularAPIView
    def get(self, request, *args, **kwargs):
  File "/home/ec2-user/intern_python/venv/lib64/python3.9/site-packages/drf_spectacular/utils.py", line 430, in decorator
    or api_settings.DEFAULT_SCHEMA_CLASS
  File "/home/ec2-user/intern_python/venv/lib64/python3.9/site-packages/rest_framework/settings.py", line 227, in __getattr__
    val = perform_import(val, attr)
  File "/home/ec2-user/intern_python/venv/lib64/python3.9/site-packages/rest_framework/settings.py", line 168, in perform_import
    return import_from_string(val, setting_name)
  File "/home/ec2-user/intern_python/venv/lib64/python3.9/site-packages/rest_framework/settings.py", line 182, in import_from_string
    raise ImportError(msg)
ImportError: Could not import 'drf_spectacular.views.SpectacularAPIView' for API setting 'DEFAULT_SCHEMA_CLASS'. ImportError: Module "drf_spectacular.views" does not define a "SpectacularAPIView" attribute/class.
[2025-06-14 07:17:25 +0000] [28062] [ERROR] Error handling request /swagger
Traceback (most recent call last):
  File "/home/ec2-user/intern_python/venv/lib64/python3.9/site-packages/django/utils/module_loading.py", line 30, in import_string
    return cached_import(module_path, class_name)
  File "/home/ec2-user/intern_python/venv/lib64/python3.9/site-packages/django/utils/module_loading.py", line 16, in cached_import
    return getattr(module, class_name)
AttributeError: partially initialized module 'drf_spectacular.views' has no attribute 'SpectacularAPIView' (most likely due to a circular import)

The above exception was the direct cause of the following exception:

Traceback (most recent call last):
  File "/home/ec2-user/intern_python/venv/lib64/python3.9/site-packages/rest_framework/settings.py", line 179, in import_from_string
    return import_string(val)
  File "/home/ec2-user/intern_python/venv/lib64/python3.9/site-packages/django/utils/module_loading.py", line 32, in import_string
    raise ImportError(
ImportError: Module "drf_spectacular.views" does not define a "SpectacularAPIView" attribute/class

During handling of the above exception, another exception occurred:

Traceback (most recent call last):
  File "/home/ec2-user/intern_python/venv/lib64/python3.9/site-packages/django/core/handlers/exception.py", line 55, in inner
    response = get_response(request)
  File "/home/ec2-user/intern_python/venv/lib64/python3.9/site-packages/django/core/handlers/base.py", line 181, in _get_response
    callback, callback_args, callback_kwargs = self.resolve_request(request)
  File "/home/ec2-user/intern_python/venv/lib64/python3.9/site-packages/django/core/handlers/base.py", line 313, in resolve_request
    resolver_match = resolver.resolve(request.path_info)
  File "/home/ec2-user/intern_python/venv/lib64/python3.9/site-packages/django/urls/resolvers.py", line 663, in resolve
    for pattern in self.url_patterns:
  File "/home/ec2-user/intern_python/venv/lib64/python3.9/site-packages/django/utils/functional.py", line 57, in __get__
    res = instance.__dict__[self.name] = self.func(instance)
  File "/home/ec2-user/intern_python/venv/lib64/python3.9/site-packages/django/urls/resolvers.py", line 715, in url_patterns
    patterns = getattr(self.urlconf_module, "urlpatterns", self.urlconf_module)
  File "/home/ec2-user/intern_python/venv/lib64/python3.9/site-packages/django/utils/functional.py", line 57, in __get__
    res = instance.__dict__[self.name] = self.func(instance)
  File "/home/ec2-user/intern_python/venv/lib64/python3.9/site-packages/django/urls/resolvers.py", line 708, in urlconf_module
    return import_module(self.urlconf_name)
  File "/usr/lib64/python3.9/importlib/__init__.py", line 127, in import_module
    return _bootstrap._gcd_import(name[level:], package, level)
  File "<frozen importlib._bootstrap>", line 1030, in _gcd_import
  File "<frozen importlib._bootstrap>", line 1007, in _find_and_load
  File "<frozen importlib._bootstrap>", line 986, in _find_and_load_unlocked
  File "<frozen importlib._bootstrap>", line 680, in _load_unlocked
  File "<frozen importlib._bootstrap_external>", line 850, in exec_module
  File "<frozen importlib._bootstrap>", line 228, in _call_with_frames_removed
  File "/home/ec2-user/intern_python/python/urls.py", line 4, in <module>
    from drf_spectacular.views import SpectacularAPIView, SpectacularSwaggerView
  File "/home/ec2-user/intern_python/venv/lib64/python3.9/site-packages/drf_spectacular/views.py", line 44, in <module>
    class SpectacularAPIView(APIView):
  File "/home/ec2-user/intern_python/venv/lib64/python3.9/site-packages/drf_spectacular/views.py", line 64, in SpectacularAPIView
    def get(self, request, *args, **kwargs):
  File "/home/ec2-user/intern_python/venv/lib64/python3.9/site-packages/drf_spectacular/utils.py", line 430, in decorator
    or api_settings.DEFAULT_SCHEMA_CLASS
  File "/home/ec2-user/intern_python/venv/lib64/python3.9/site-packages/rest_framework/settings.py", line 227, in __getattr__
    val = perform_import(val, attr)
  File "/home/ec2-user/intern_python/venv/lib64/python3.9/site-packages/rest_framework/settings.py", line 168, in perform_import
    return import_from_string(val, setting_name)
  File "/home/ec2-user/intern_python/venv/lib64/python3.9/site-packages/rest_framework/settings.py", line 182, in import_from_string
    raise ImportError(msg)
ImportError: Could not import 'drf_spectacular.views.SpectacularAPIView' for API setting 'DEFAULT_SCHEMA_CLASS'. ImportError: Module "drf_spectacular.views" does not define a "SpectacularAPIView" attribute/class.

During handling of the above exception, another exception occurred:

Traceback (most recent call last):
  File "/home/ec2-user/intern_python/venv/lib64/python3.9/site-packages/django/utils/module_loading.py", line 30, in import_string
    return cached_import(module_path, class_name)
  File "/home/ec2-user/intern_python/venv/lib64/python3.9/site-packages/django/utils/module_loading.py", line 16, in cached_import
    return getattr(module, class_name)
AttributeError: partially initialized module 'drf_spectacular.views' has no attribute 'SpectacularAPIView' (most likely due to a circular import)

The above exception was the direct cause of the following exception:

Traceback (most recent call last):
  File "/home/ec2-user/intern_python/venv/lib64/python3.9/site-packages/rest_framework/settings.py", line 179, in import_from_string
    return import_string(val)
  File "/home/ec2-user/intern_python/venv/lib64/python3.9/site-packages/django/utils/module_loading.py", line 32, in import_string
    raise ImportError(
ImportError: Module "drf_spectacular.views" does not define a "SpectacularAPIView" attribute/class

During handling of the above exception, another exception occurred:

Traceback (most recent call last):
  File "/home/ec2-user/intern_python/venv/lib64/python3.9/site-packages/django/core/handlers/exception.py", line 55, in inner
    response = get_response(request)
  File "/home/ec2-user/intern_python/venv/lib64/python3.9/site-packages/django/utils/deprecation.py", line 134, in __call__
    response = response or self.get_response(request)
  File "/home/ec2-user/intern_python/venv/lib64/python3.9/site-packages/django/core/handlers/exception.py", line 57, in inner
    response = response_for_exception(request, exc)
  File "/home/ec2-user/intern_python/venv/lib64/python3.9/site-packages/django/core/handlers/exception.py", line 141, in response_for_exception
    response = handle_uncaught_exception(
  File "/home/ec2-user/intern_python/venv/lib64/python3.9/site-packages/django/core/handlers/exception.py", line 182, in handle_uncaught_exception
    return debug.technical_500_response(request, *exc_info)
  File "/home/ec2-user/intern_python/venv/lib64/python3.9/site-packages/django/views/debug.py", line 67, in technical_500_response
    html = reporter.get_traceback_html()
  File "/home/ec2-user/intern_python/venv/lib64/python3.9/site-packages/django/views/debug.py", line 410, in get_traceback_html
    c = Context(self.get_traceback_data(), use_l10n=False)
  File "/home/ec2-user/intern_python/venv/lib64/python3.9/site-packages/django/views/debug.py", line 393, in get_traceback_data
    c["raising_view_name"] = get_caller(self.request)
  File "/home/ec2-user/intern_python/venv/lib64/python3.9/site-packages/django/views/debug.py", line 100, in get_caller
    resolver_match = resolve(request.path)
  File "/home/ec2-user/intern_python/venv/lib64/python3.9/site-packages/django/urls/base.py", line 24, in resolve
    return get_resolver(urlconf).resolve(path)
  File "/home/ec2-user/intern_python/venv/lib64/python3.9/site-packages/django/urls/resolvers.py", line 663, in resolve
    for pattern in self.url_patterns:
  File "/home/ec2-user/intern_python/venv/lib64/python3.9/site-packages/django/utils/functional.py", line 57, in __get__
    res = instance.__dict__[self.name] = self.func(instance)
  File "/home/ec2-user/intern_python/venv/lib64/python3.9/site-packages/django/urls/resolvers.py", line 715, in url_patterns
    patterns = getattr(self.urlconf_module, "urlpatterns", self.urlconf_module)
  File "/home/ec2-user/intern_python/venv/lib64/python3.9/site-packages/django/utils/functional.py", line 57, in __get__
    res = instance.__dict__[self.name] = self.func(instance)
  File "/home/ec2-user/intern_python/venv/lib64/python3.9/site-packages/django/urls/resolvers.py", line 708, in urlconf_module
    return import_module(self.urlconf_name)
  File "/usr/lib64/python3.9/importlib/__init__.py", line 127, in import_module
    return _bootstrap._gcd_import(name[level:], package, level)
  File "<frozen importlib._bootstrap>", line 1030, in _gcd_import
  File "<frozen importlib._bootstrap>", line 1007, in _find_and_load
  File "<frozen importlib._bootstrap>", line 986, in _find_and_load_unlocked
  File "<frozen importlib._bootstrap>", line 680, in _load_unlocked
  File "<frozen importlib._bootstrap_external>", line 850, in exec_module
  File "<frozen importlib._bootstrap>", line 228, in _call_with_frames_removed
  File "/home/ec2-user/intern_python/python/urls.py", line 4, in <module>
    from drf_spectacular.views import SpectacularAPIView, SpectacularSwaggerView
  File "/home/ec2-user/intern_python/venv/lib64/python3.9/site-packages/drf_spectacular/views.py", line 44, in <module>
    class SpectacularAPIView(APIView):
  File "/home/ec2-user/intern_python/venv/lib64/python3.9/site-packages/drf_spectacular/views.py", line 64, in SpectacularAPIView
    def get(self, request, *args, **kwargs):
  File "/home/ec2-user/intern_python/venv/lib64/python3.9/site-packages/drf_spectacular/utils.py", line 430, in decorator
    or api_settings.DEFAULT_SCHEMA_CLASS
  File "/home/ec2-user/intern_python/venv/lib64/python3.9/site-packages/rest_framework/settings.py", line 227, in __getattr__
    val = perform_import(val, attr)
  File "/home/ec2-user/intern_python/venv/lib64/python3.9/site-packages/rest_framework/settings.py", line 168, in perform_import
    return import_from_string(val, setting_name)
  File "/home/ec2-user/intern_python/venv/lib64/python3.9/site-packages/rest_framework/settings.py", line 182, in import_from_string
    raise ImportError(msg)
ImportError: Could not import 'drf_spectacular.views.SpectacularAPIView' for API setting 'DEFAULT_SCHEMA_CLASS'. ImportError: Module "drf_spectacular.views" does not define a "SpectacularAPIView" attribute/class.

During handling of the above exception, another exception occurred:

Traceback (most recent call last):
  File "/home/ec2-user/intern_python/venv/lib64/python3.9/site-packages/django/utils/module_loading.py", line 30, in import_string
    return cached_import(module_path, class_name)
  File "/home/ec2-user/intern_python/venv/lib64/python3.9/site-packages/django/utils/module_loading.py", line 16, in cached_import
    return getattr(module, class_name)
AttributeError: partially initialized module 'drf_spectacular.views' has no attribute 'SpectacularAPIView' (most likely due to a circular import)

The above exception was the direct cause of the following exception:

Traceback (most recent call last):
  File "/home/ec2-user/intern_python/venv/lib64/python3.9/site-packages/rest_framework/settings.py", line 179, in import_from_string
    return import_string(val)
  File "/home/ec2-user/intern_python/venv/lib64/python3.9/site-packages/django/utils/module_loading.py", line 32, in import_string
    raise ImportError(
ImportError: Module "drf_spectacular.views" does not define a "SpectacularAPIView" attribute/class

During handling of the above exception, another exception occurred:

Traceback (most recent call last):
  File "/home/ec2-user/intern_python/venv/lib64/python3.9/site-packages/django/core/handlers/exception.py", line 55, in inner
    response = get_response(request)
  File "/home/ec2-user/intern_python/venv/lib64/python3.9/site-packages/django/utils/deprecation.py", line 134, in __call__
    response = response or self.get_response(request)
  File "/home/ec2-user/intern_python/venv/lib64/python3.9/site-packages/django/core/handlers/exception.py", line 57, in inner
    response = response_for_exception(request, exc)
  File "/home/ec2-user/intern_python/venv/lib64/python3.9/site-packages/django/core/handlers/exception.py", line 141, in response_for_exception
    response = handle_uncaught_exception(
  File "/home/ec2-user/intern_python/venv/lib64/python3.9/site-packages/django/core/handlers/exception.py", line 182, in handle_uncaught_exception
    return debug.technical_500_response(request, *exc_info)
  File "/home/ec2-user/intern_python/venv/lib64/python3.9/site-packages/django/views/debug.py", line 67, in technical_500_response
    html = reporter.get_traceback_html()
  File "/home/ec2-user/intern_python/venv/lib64/python3.9/site-packages/django/views/debug.py", line 410, in get_traceback_html
    c = Context(self.get_traceback_data(), use_l10n=False)
  File "/home/ec2-user/intern_python/venv/lib64/python3.9/site-packages/django/views/debug.py", line 393, in get_traceback_data
    c["raising_view_name"] = get_caller(self.request)
  File "/home/ec2-user/intern_python/venv/lib64/python3.9/site-packages/django/views/debug.py", line 100, in get_caller
    resolver_match = resolve(request.path)
  File "/home/ec2-user/intern_python/venv/lib64/python3.9/site-packages/django/urls/base.py", line 24, in resolve
    return get_resolver(urlconf).resolve(path)
  File "/home/ec2-user/intern_python/venv/lib64/python3.9/site-packages/django/urls/resolvers.py", line 663, in resolve
    for pattern in self.url_patterns:
  File "/home/ec2-user/intern_python/venv/lib64/python3.9/site-packages/django/utils/functional.py", line 57, in __get__
    res = instance.__dict__[self.name] = self.func(instance)
  File "/home/ec2-user/intern_python/venv/lib64/python3.9/site-packages/django/urls/resolvers.py", line 715, in url_patterns
    patterns = getattr(self.urlconf_module, "urlpatterns", self.urlconf_module)
  File "/home/ec2-user/intern_python/venv/lib64/python3.9/site-packages/django/utils/functional.py", line 57, in __get__
    res = instance.__dict__[self.name] = self.func(instance)
  File "/home/ec2-user/intern_python/venv/lib64/python3.9/site-packages/django/urls/resolvers.py", line 708, in urlconf_module
    return import_module(self.urlconf_name)
  File "/usr/lib64/python3.9/importlib/__init__.py", line 127, in import_module
    return _bootstrap._gcd_import(name[level:], package, level)
  File "<frozen importlib._bootstrap>", line 1030, in _gcd_import
  File "<frozen importlib._bootstrap>", line 1007, in _find_and_load
  File "<frozen importlib._bootstrap>", line 986, in _find_and_load_unlocked
  File "<frozen importlib._bootstrap>", line 680, in _load_unlocked
  File "<frozen importlib._bootstrap_external>", line 850, in exec_module
  File "<frozen importlib._bootstrap>", line 228, in _call_with_frames_removed
  File "/home/ec2-user/intern_python/python/urls.py", line 4, in <module>
    from drf_spectacular.views import SpectacularAPIView, SpectacularSwaggerView
  File "/home/ec2-user/intern_python/venv/lib64/python3.9/site-packages/drf_spectacular/views.py", line 44, in <module>
    class SpectacularAPIView(APIView):
  File "/home/ec2-user/intern_python/venv/lib64/python3.9/site-packages/drf_spectacular/views.py", line 64, in SpectacularAPIView
    def get(self, request, *args, **kwargs):
  File "/home/ec2-user/intern_python/venv/lib64/python3.9/site-packages/drf_spectacular/utils.py", line 430, in decorator
    or api_settings.DEFAULT_SCHEMA_CLASS
  File "/home/ec2-user/intern_python/venv/lib64/python3.9/site-packages/rest_framework/settings.py", line 227, in __getattr__
    val = perform_import(val, attr)
  File "/home/ec2-user/intern_python/venv/lib64/python3.9/site-packages/rest_framework/settings.py", line 168, in perform_import
    return import_from_string(val, setting_name)
  File "/home/ec2-user/intern_python/venv/lib64/python3.9/site-packages/rest_framework/settings.py", line 182, in import_from_string
    raise ImportError(msg)
ImportError: Could not import 'drf_spectacular.views.SpectacularAPIView' for API setting 'DEFAULT_SCHEMA_CLASS'. ImportError: Module "drf_spectacular.views" does not define a "SpectacularAPIView" attribute/class.

During handling of the above exception, another exception occurred:

Traceback (most recent call last):
  File "/home/ec2-user/intern_python/venv/lib64/python3.9/site-packages/django/utils/module_loading.py", line 30, in import_string
    return cached_import(module_path, class_name)
  File "/home/ec2-user/intern_python/venv/lib64/python3.9/site-packages/django/utils/module_loading.py", line 16, in cached_import
    return getattr(module, class_name)
AttributeError: partially initialized module 'drf_spectacular.views' has no attribute 'SpectacularAPIView' (most likely due to a circular import)

The above exception was the direct cause of the following exception:

Traceback (most recent call last):
  File "/home/ec2-user/intern_python/venv/lib64/python3.9/site-packages/rest_framework/settings.py", line 179, in import_from_string
    return import_string(val)
  File "/home/ec2-user/intern_python/venv/lib64/python3.9/site-packages/django/utils/module_loading.py", line 32, in import_string
    raise ImportError(
ImportError: Module "drf_spectacular.views" does not define a "SpectacularAPIView" attribute/class

During handling of the above exception, another exception occurred:

Traceback (most recent call last):
  File "/home/ec2-user/intern_python/venv/lib64/python3.9/site-packages/django/core/handlers/exception.py", line 55, in inner
    response = get_response(request)
  File "/home/ec2-user/intern_python/venv/lib64/python3.9/site-packages/django/utils/deprecation.py", line 134, in __call__
    response = response or self.get_response(request)
  File "/home/ec2-user/intern_python/venv/lib64/python3.9/site-packages/django/core/handlers/exception.py", line 57, in inner
    response = response_for_exception(request, exc)
  File "/home/ec2-user/intern_python/venv/lib64/python3.9/site-packages/django/core/handlers/exception.py", line 141, in response_for_exception
    response = handle_uncaught_exception(
  File "/home/ec2-user/intern_python/venv/lib64/python3.9/site-packages/django/core/handlers/exception.py", line 182, in handle_uncaught_exception
    return debug.technical_500_response(request, *exc_info)
  File "/home/ec2-user/intern_python/venv/lib64/python3.9/site-packages/django/views/debug.py", line 67, in technical_500_response
    html = reporter.get_traceback_html()
  File "/home/ec2-user/intern_python/venv/lib64/python3.9/site-packages/django/views/debug.py", line 410, in get_traceback_html
    c = Context(self.get_traceback_data(), use_l10n=False)
  File "/home/ec2-user/intern_python/venv/lib64/python3.9/site-packages/django/views/debug.py", line 393, in get_traceback_data
    c["raising_view_name"] = get_caller(self.request)
  File "/home/ec2-user/intern_python/venv/lib64/python3.9/site-packages/django/views/debug.py", line 100, in get_caller
    resolver_match = resolve(request.path)
  File "/home/ec2-user/intern_python/venv/lib64/python3.9/site-packages/django/urls/base.py", line 24, in resolve
    return get_resolver(urlconf).resolve(path)
  File "/home/ec2-user/intern_python/venv/lib64/python3.9/site-packages/django/urls/resolvers.py", line 663, in resolve
    for pattern in self.url_patterns:
  File "/home/ec2-user/intern_python/venv/lib64/python3.9/site-packages/django/utils/functional.py", line 57, in __get__
    res = instance.__dict__[self.name] = self.func(instance)
  File "/home/ec2-user/intern_python/venv/lib64/python3.9/site-packages/django/urls/resolvers.py", line 715, in url_patterns
    patterns = getattr(self.urlconf_module, "urlpatterns", self.urlconf_module)
  File "/home/ec2-user/intern_python/venv/lib64/python3.9/site-packages/django/utils/functional.py", line 57, in __get__
    res = instance.__dict__[self.name] = self.func(instance)
  File "/home/ec2-user/intern_python/venv/lib64/python3.9/site-packages/django/urls/resolvers.py", line 708, in urlconf_module
    return import_module(self.urlconf_name)
  File "/usr/lib64/python3.9/importlib/__init__.py", line 127, in import_module
    return _bootstrap._gcd_import(name[level:], package, level)
  File "<frozen importlib._bootstrap>", line 1030, in _gcd_import
  File "<frozen importlib._bootstrap>", line 1007, in _find_and_load
  File "<frozen importlib._bootstrap>", line 986, in _find_and_load_unlocked
  File "<frozen importlib._bootstrap>", line 680, in _load_unlocked
  File "<frozen importlib._bootstrap_external>", line 850, in exec_module
  File "<frozen importlib._bootstrap>", line 228, in _call_with_frames_removed
  File "/home/ec2-user/intern_python/python/urls.py", line 4, in <module>
    from drf_spectacular.views import SpectacularAPIView, SpectacularSwaggerView
  File "/home/ec2-user/intern_python/venv/lib64/python3.9/site-packages/drf_spectacular/views.py", line 44, in <module>
    class SpectacularAPIView(APIView):
  File "/home/ec2-user/intern_python/venv/lib64/python3.9/site-packages/drf_spectacular/views.py", line 64, in SpectacularAPIView
    def get(self, request, *args, **kwargs):
  File "/home/ec2-user/intern_python/venv/lib64/python3.9/site-packages/drf_spectacular/utils.py", line 430, in decorator
    or api_settings.DEFAULT_SCHEMA_CLASS
  File "/home/ec2-user/intern_python/venv/lib64/python3.9/site-packages/rest_framework/settings.py", line 227, in __getattr__
    val = perform_import(val, attr)
  File "/home/ec2-user/intern_python/venv/lib64/python3.9/site-packages/rest_framework/settings.py", line 168, in perform_import
    return import_from_string(val, setting_name)
  File "/home/ec2-user/intern_python/venv/lib64/python3.9/site-packages/rest_framework/settings.py", line 182, in import_from_string
    raise ImportError(msg)
ImportError: Could not import 'drf_spectacular.views.SpectacularAPIView' for API setting 'DEFAULT_SCHEMA_CLASS'. ImportError: Module "drf_spectacular.views" does not define a "SpectacularAPIView" attribute/class.

During handling of the above exception, another exception occurred:

Traceback (most recent call last):
  File "/home/ec2-user/intern_python/venv/lib64/python3.9/site-packages/django/utils/module_loading.py", line 30, in import_string
    return cached_import(module_path, class_name)
  File "/home/ec2-user/intern_python/venv/lib64/python3.9/site-packages/django/utils/module_loading.py", line 16, in cached_import
    return getattr(module, class_name)
AttributeError: partially initialized module 'drf_spectacular.views' has no attribute 'SpectacularAPIView' (most likely due to a circular import)

The above exception was the direct cause of the following exception:

Traceback (most recent call last):
  File "/home/ec2-user/intern_python/venv/lib64/python3.9/site-packages/rest_framework/settings.py", line 179, in import_from_string
    return import_string(val)
  File "/home/ec2-user/intern_python/venv/lib64/python3.9/site-packages/django/utils/module_loading.py", line 32, in import_string
    raise ImportError(
ImportError: Module "drf_spectacular.views" does not define a "SpectacularAPIView" attribute/class

During handling of the above exception, another exception occurred:

Traceback (most recent call last):
  File "/home/ec2-user/intern_python/venv/lib64/python3.9/site-packages/django/core/handlers/exception.py", line 55, in inner
    response = get_response(request)
  File "/home/ec2-user/intern_python/venv/lib64/python3.9/site-packages/django/utils/deprecation.py", line 134, in __call__
    response = response or self.get_response(request)
  File "/home/ec2-user/intern_python/venv/lib64/python3.9/site-packages/django/core/handlers/exception.py", line 57, in inner
    response = response_for_exception(request, exc)
  File "/home/ec2-user/intern_python/venv/lib64/python3.9/site-packages/django/core/handlers/exception.py", line 141, in response_for_exception
    response = handle_uncaught_exception(
  File "/home/ec2-user/intern_python/venv/lib64/python3.9/site-packages/django/core/handlers/exception.py", line 182, in handle_uncaught_exception
    return debug.technical_500_response(request, *exc_info)
  File "/home/ec2-user/intern_python/venv/lib64/python3.9/site-packages/django/views/debug.py", line 67, in technical_500_response
    html = reporter.get_traceback_html()
  File "/home/ec2-user/intern_python/venv/lib64/python3.9/site-packages/django/views/debug.py", line 410, in get_traceback_html
    c = Context(self.get_traceback_data(), use_l10n=False)
  File "/home/ec2-user/intern_python/venv/lib64/python3.9/site-packages/django/views/debug.py", line 393, in get_traceback_data
    c["raising_view_name"] = get_caller(self.request)
  File "/home/ec2-user/intern_python/venv/lib64/python3.9/site-packages/django/views/debug.py", line 100, in get_caller
    resolver_match = resolve(request.path)
  File "/home/ec2-user/intern_python/venv/lib64/python3.9/site-packages/django/urls/base.py", line 24, in resolve
    return get_resolver(urlconf).resolve(path)
  File "/home/ec2-user/intern_python/venv/lib64/python3.9/site-packages/django/urls/resolvers.py", line 663, in resolve
    for pattern in self.url_patterns:
  File "/home/ec2-user/intern_python/venv/lib64/python3.9/site-packages/django/utils/functional.py", line 57, in __get__
    res = instance.__dict__[self.name] = self.func(instance)
  File "/home/ec2-user/intern_python/venv/lib64/python3.9/site-packages/django/urls/resolvers.py", line 715, in url_patterns
    patterns = getattr(self.urlconf_module, "urlpatterns", self.urlconf_module)
  File "/home/ec2-user/intern_python/venv/lib64/python3.9/site-packages/django/utils/functional.py", line 57, in __get__
    res = instance.__dict__[self.name] = self.func(instance)
  File "/home/ec2-user/intern_python/venv/lib64/python3.9/site-packages/django/urls/resolvers.py", line 708, in urlconf_module
    return import_module(self.urlconf_name)
  File "/usr/lib64/python3.9/importlib/__init__.py", line 127, in import_module
    return _bootstrap._gcd_import(name[level:], package, level)
  File "<frozen importlib._bootstrap>", line 1030, in _gcd_import
  File "<frozen importlib._bootstrap>", line 1007, in _find_and_load
  File "<frozen importlib._bootstrap>", line 986, in _find_and_load_unlocked
  File "<frozen importlib._bootstrap>", line 680, in _load_unlocked
  File "<frozen importlib._bootstrap_external>", line 850, in exec_module
  File "<frozen importlib._bootstrap>", line 228, in _call_with_frames_removed
  File "/home/ec2-user/intern_python/python/urls.py", line 4, in <module>
    from drf_spectacular.views import SpectacularAPIView, SpectacularSwaggerView
  File "/home/ec2-user/intern_python/venv/lib64/python3.9/site-packages/drf_spectacular/views.py", line 44, in <module>
    class SpectacularAPIView(APIView):
  File "/home/ec2-user/intern_python/venv/lib64/python3.9/site-packages/drf_spectacular/views.py", line 64, in SpectacularAPIView
    def get(self, request, *args, **kwargs):
  File "/home/ec2-user/intern_python/venv/lib64/python3.9/site-packages/drf_spectacular/utils.py", line 430, in decorator
    or api_settings.DEFAULT_SCHEMA_CLASS
  File "/home/ec2-user/intern_python/venv/lib64/python3.9/site-packages/rest_framework/settings.py", line 227, in __getattr__
    val = perform_import(val, attr)
  File "/home/ec2-user/intern_python/venv/lib64/python3.9/site-packages/rest_framework/settings.py", line 168, in perform_import
    return import_from_string(val, setting_name)
  File "/home/ec2-user/intern_python/venv/lib64/python3.9/site-packages/rest_framework/settings.py", line 182, in import_from_string
    raise ImportError(msg)
ImportError: Could not import 'drf_spectacular.views.SpectacularAPIView' for API setting 'DEFAULT_SCHEMA_CLASS'. ImportError: Module "drf_spectacular.views" does not define a "SpectacularAPIView" attribute/class.

During handling of the above exception, another exception occurred:

Traceback (most recent call last):
  File "/home/ec2-user/intern_python/venv/lib64/python3.9/site-packages/django/utils/module_loading.py", line 30, in import_string
    return cached_import(module_path, class_name)
  File "/home/ec2-user/intern_python/venv/lib64/python3.9/site-packages/django/utils/module_loading.py", line 16, in cached_import
    return getattr(module, class_name)
AttributeError: partially initialized module 'drf_spectacular.views' has no attribute 'SpectacularAPIView' (most likely due to a circular import)

The above exception was the direct cause of the following exception:

Traceback (most recent call last):
  File "/home/ec2-user/intern_python/venv/lib64/python3.9/site-packages/rest_framework/settings.py", line 179, in import_from_string
    return import_string(val)
  File "/home/ec2-user/intern_python/venv/lib64/python3.9/site-packages/django/utils/module_loading.py", line 32, in import_string
    raise ImportError(
ImportError: Module "drf_spectacular.views" does not define a "SpectacularAPIView" attribute/class

During handling of the above exception, another exception occurred:

Traceback (most recent call last):
  File "/home/ec2-user/intern_python/venv/lib64/python3.9/site-packages/django/core/handlers/exception.py", line 55, in inner
    response = get_response(request)
  File "/home/ec2-user/intern_python/venv/lib64/python3.9/site-packages/django/utils/deprecation.py", line 134, in __call__
    response = response or self.get_response(request)
  File "/home/ec2-user/intern_python/venv/lib64/python3.9/site-packages/django/core/handlers/exception.py", line 57, in inner
    response = response_for_exception(request, exc)
  File "/home/ec2-user/intern_python/venv/lib64/python3.9/site-packages/django/core/handlers/exception.py", line 141, in response_for_exception
    response = handle_uncaught_exception(
  File "/home/ec2-user/intern_python/venv/lib64/python3.9/site-packages/django/core/handlers/exception.py", line 182, in handle_uncaught_exception
    return debug.technical_500_response(request, *exc_info)
  File "/home/ec2-user/intern_python/venv/lib64/python3.9/site-packages/django/views/debug.py", line 67, in technical_500_response
    html = reporter.get_traceback_html()
  File "/home/ec2-user/intern_python/venv/lib64/python3.9/site-packages/django/views/debug.py", line 410, in get_traceback_html
    c = Context(self.get_traceback_data(), use_l10n=False)
  File "/home/ec2-user/intern_python/venv/lib64/python3.9/site-packages/django/views/debug.py", line 393, in get_traceback_data
    c["raising_view_name"] = get_caller(self.request)
  File "/home/ec2-user/intern_python/venv/lib64/python3.9/site-packages/django/views/debug.py", line 100, in get_caller
    resolver_match = resolve(request.path)
  File "/home/ec2-user/intern_python/venv/lib64/python3.9/site-packages/django/urls/base.py", line 24, in resolve
    return get_resolver(urlconf).resolve(path)
  File "/home/ec2-user/intern_python/venv/lib64/python3.9/site-packages/django/urls/resolvers.py", line 663, in resolve
    for pattern in self.url_patterns:
  File "/home/ec2-user/intern_python/venv/lib64/python3.9/site-packages/django/utils/functional.py", line 57, in __get__
    res = instance.__dict__[self.name] = self.func(instance)
  File "/home/ec2-user/intern_python/venv/lib64/python3.9/site-packages/django/urls/resolvers.py", line 715, in url_patterns
    patterns = getattr(self.urlconf_module, "urlpatterns", self.urlconf_module)
  File "/home/ec2-user/intern_python/venv/lib64/python3.9/site-packages/django/utils/functional.py", line 57, in __get__
    res = instance.__dict__[self.name] = self.func(instance)
  File "/home/ec2-user/intern_python/venv/lib64/python3.9/site-packages/django/urls/resolvers.py", line 708, in urlconf_module
    return import_module(self.urlconf_name)
  File "/usr/lib64/python3.9/importlib/__init__.py", line 127, in import_module
    return _bootstrap._gcd_import(name[level:], package, level)
  File "<frozen importlib._bootstrap>", line 1030, in _gcd_import
  File "<frozen importlib._bootstrap>", line 1007, in _find_and_load
  File "<frozen importlib._bootstrap>", line 986, in _find_and_load_unlocked
  File "<frozen importlib._bootstrap>", line 680, in _load_unlocked
  File "<frozen importlib._bootstrap_external>", line 850, in exec_module
  File "<frozen importlib._bootstrap>", line 228, in _call_with_frames_removed
  File "/home/ec2-user/intern_python/python/urls.py", line 4, in <module>
    from drf_spectacular.views import SpectacularAPIView, SpectacularSwaggerView
  File "/home/ec2-user/intern_python/venv/lib64/python3.9/site-packages/drf_spectacular/views.py", line 44, in <module>
    class SpectacularAPIView(APIView):
  File "/home/ec2-user/intern_python/venv/lib64/python3.9/site-packages/drf_spectacular/views.py", line 64, in SpectacularAPIView
    def get(self, request, *args, **kwargs):
  File "/home/ec2-user/intern_python/venv/lib64/python3.9/site-packages/drf_spectacular/utils.py", line 430, in decorator
    or api_settings.DEFAULT_SCHEMA_CLASS
  File "/home/ec2-user/intern_python/venv/lib64/python3.9/site-packages/rest_framework/settings.py", line 227, in __getattr__
    val = perform_import(val, attr)
  File "/home/ec2-user/intern_python/venv/lib64/python3.9/site-packages/rest_framework/settings.py", line 168, in perform_import
    return import_from_string(val, setting_name)
  File "/home/ec2-user/intern_python/venv/lib64/python3.9/site-packages/rest_framework/settings.py", line 182, in import_from_string
    raise ImportError(msg)
ImportError: Could not import 'drf_spectacular.views.SpectacularAPIView' for API setting 'DEFAULT_SCHEMA_CLASS'. ImportError: Module "drf_spectacular.views" does not define a "SpectacularAPIView" attribute/class.

During handling of the above exception, another exception occurred:

Traceback (most recent call last):
  File "/home/ec2-user/intern_python/venv/lib64/python3.9/site-packages/django/utils/module_loading.py", line 30, in import_string
    return cached_import(module_path, class_name)
  File "/home/ec2-user/intern_python/venv/lib64/python3.9/site-packages/django/utils/module_loading.py", line 16, in cached_import
    return getattr(module, class_name)
AttributeError: partially initialized module 'drf_spectacular.views' has no attribute 'SpectacularAPIView' (most likely due to a circular import)

The above exception was the direct cause of the following exception:

Traceback (most recent call last):
  File "/home/ec2-user/intern_python/venv/lib64/python3.9/site-packages/rest_framework/settings.py", line 179, in import_from_string
    return import_string(val)
  File "/home/ec2-user/intern_python/venv/lib64/python3.9/site-packages/django/utils/module_loading.py", line 32, in import_string
    raise ImportError(
ImportError: Module "drf_spectacular.views" does not define a "SpectacularAPIView" attribute/class

During handling of the above exception, another exception occurred:

Traceback (most recent call last):
  File "/home/ec2-user/intern_python/venv/lib64/python3.9/site-packages/django/core/handlers/exception.py", line 55, in inner
    response = get_response(request)
  File "/home/ec2-user/intern_python/venv/lib64/python3.9/site-packages/django/utils/deprecation.py", line 134, in __call__
    response = response or self.get_response(request)
  File "/home/ec2-user/intern_python/venv/lib64/python3.9/site-packages/django/core/handlers/exception.py", line 57, in inner
    response = response_for_exception(request, exc)
  File "/home/ec2-user/intern_python/venv/lib64/python3.9/site-packages/django/core/handlers/exception.py", line 141, in response_for_exception
    response = handle_uncaught_exception(
  File "/home/ec2-user/intern_python/venv/lib64/python3.9/site-packages/django/core/handlers/exception.py", line 182, in handle_uncaught_exception
    return debug.technical_500_response(request, *exc_info)
  File "/home/ec2-user/intern_python/venv/lib64/python3.9/site-packages/django/views/debug.py", line 67, in technical_500_response
    html = reporter.get_traceback_html()
  File "/home/ec2-user/intern_python/venv/lib64/python3.9/site-packages/django/views/debug.py", line 410, in get_traceback_html
    c = Context(self.get_traceback_data(), use_l10n=False)
  File "/home/ec2-user/intern_python/venv/lib64/python3.9/site-packages/django/views/debug.py", line 393, in get_traceback_data
    c["raising_view_name"] = get_caller(self.request)
  File "/home/ec2-user/intern_python/venv/lib64/python3.9/site-packages/django/views/debug.py", line 100, in get_caller
    resolver_match = resolve(request.path)
  File "/home/ec2-user/intern_python/venv/lib64/python3.9/site-packages/django/urls/base.py", line 24, in resolve
    return get_resolver(urlconf).resolve(path)
  File "/home/ec2-user/intern_python/venv/lib64/python3.9/site-packages/django/urls/resolvers.py", line 663, in resolve
    for pattern in self.url_patterns:
  File "/home/ec2-user/intern_python/venv/lib64/python3.9/site-packages/django/utils/functional.py", line 57, in __get__
    res = instance.__dict__[self.name] = self.func(instance)
  File "/home/ec2-user/intern_python/venv/lib64/python3.9/site-packages/django/urls/resolvers.py", line 715, in url_patterns
    patterns = getattr(self.urlconf_module, "urlpatterns", self.urlconf_module)
  File "/home/ec2-user/intern_python/venv/lib64/python3.9/site-packages/django/utils/functional.py", line 57, in __get__
    res = instance.__dict__[self.name] = self.func(instance)
  File "/home/ec2-user/intern_python/venv/lib64/python3.9/site-packages/django/urls/resolvers.py", line 708, in urlconf_module
    return import_module(self.urlconf_name)
  File "/usr/lib64/python3.9/importlib/__init__.py", line 127, in import_module
    return _bootstrap._gcd_import(name[level:], package, level)
  File "<frozen importlib._bootstrap>", line 1030, in _gcd_import
  File "<frozen importlib._bootstrap>", line 1007, in _find_and_load
  File "<frozen importlib._bootstrap>", line 986, in _find_and_load_unlocked
  File "<frozen importlib._bootstrap>", line 680, in _load_unlocked
  File "<frozen importlib._bootstrap_external>", line 850, in exec_module
  File "<frozen importlib._bootstrap>", line 228, in _call_with_frames_removed
  File "/home/ec2-user/intern_python/python/urls.py", line 4, in <module>
    from drf_spectacular.views import SpectacularAPIView, SpectacularSwaggerView
  File "/home/ec2-user/intern_python/venv/lib64/python3.9/site-packages/drf_spectacular/views.py", line 44, in <module>
    class SpectacularAPIView(APIView):
  File "/home/ec2-user/intern_python/venv/lib64/python3.9/site-packages/drf_spectacular/views.py", line 64, in SpectacularAPIView
    def get(self, request, *args, **kwargs):
  File "/home/ec2-user/intern_python/venv/lib64/python3.9/site-packages/drf_spectacular/utils.py", line 430, in decorator
    or api_settings.DEFAULT_SCHEMA_CLASS
  File "/home/ec2-user/intern_python/venv/lib64/python3.9/site-packages/rest_framework/settings.py", line 227, in __getattr__
    val = perform_import(val, attr)
  File "/home/ec2-user/intern_python/venv/lib64/python3.9/site-packages/rest_framework/settings.py", line 168, in perform_import
    return import_from_string(val, setting_name)
  File "/home/ec2-user/intern_python/venv/lib64/python3.9/site-packages/rest_framework/settings.py", line 182, in import_from_string
    raise ImportError(msg)
ImportError: Could not import 'drf_spectacular.views.SpectacularAPIView' for API setting 'DEFAULT_SCHEMA_CLASS'. ImportError: Module "drf_spectacular.views" does not define a "SpectacularAPIView" attribute/class.

During handling of the above exception, another exception occurred:

Traceback (most recent call last):
  File "/home/ec2-user/intern_python/venv/lib64/python3.9/site-packages/django/utils/module_loading.py", line 30, in import_string
    return cached_import(module_path, class_name)
  File "/home/ec2-user/intern_python/venv/lib64/python3.9/site-packages/django/utils/module_loading.py", line 16, in cached_import
    return getattr(module, class_name)
AttributeError: partially initialized module 'drf_spectacular.views' has no attribute 'SpectacularAPIView' (most likely due to a circular import)

The above exception was the direct cause of the following exception:

Traceback (most recent call last):
  File "/home/ec2-user/intern_python/venv/lib64/python3.9/site-packages/rest_framework/settings.py", line 179, in import_from_string
    return import_string(val)
  File "/home/ec2-user/intern_python/venv/lib64/python3.9/site-packages/django/utils/module_loading.py", line 32, in import_string
    raise ImportError(
ImportError: Module "drf_spectacular.views" does not define a "SpectacularAPIView" attribute/class

During handling of the above exception, another exception occurred:

Traceback (most recent call last):
  File "/home/ec2-user/intern_python/venv/lib64/python3.9/site-packages/django/core/handlers/exception.py", line 55, in inner
    response = get_response(request)
  File "/home/ec2-user/intern_python/venv/lib64/python3.9/site-packages/django/utils/deprecation.py", line 134, in __call__
    response = response or self.get_response(request)
  File "/home/ec2-user/intern_python/venv/lib64/python3.9/site-packages/django/core/handlers/exception.py", line 57, in inner
    response = response_for_exception(request, exc)
  File "/home/ec2-user/intern_python/venv/lib64/python3.9/site-packages/django/core/handlers/exception.py", line 141, in response_for_exception
    response = handle_uncaught_exception(
  File "/home/ec2-user/intern_python/venv/lib64/python3.9/site-packages/django/core/handlers/exception.py", line 182, in handle_uncaught_exception
    return debug.technical_500_response(request, *exc_info)
  File "/home/ec2-user/intern_python/venv/lib64/python3.9/site-packages/django/views/debug.py", line 67, in technical_500_response
    html = reporter.get_traceback_html()
  File "/home/ec2-user/intern_python/venv/lib64/python3.9/site-packages/django/views/debug.py", line 410, in get_traceback_html
    c = Context(self.get_traceback_data(), use_l10n=False)
  File "/home/ec2-user/intern_python/venv/lib64/python3.9/site-packages/django/views/debug.py", line 393, in get_traceback_data
    c["raising_view_name"] = get_caller(self.request)
  File "/home/ec2-user/intern_python/venv/lib64/python3.9/site-packages/django/views/debug.py", line 100, in get_caller
    resolver_match = resolve(request.path)
  File "/home/ec2-user/intern_python/venv/lib64/python3.9/site-packages/django/urls/base.py", line 24, in resolve
    return get_resolver(urlconf).resolve(path)
  File "/home/ec2-user/intern_python/venv/lib64/python3.9/site-packages/django/urls/resolvers.py", line 663, in resolve
    for pattern in self.url_patterns:
  File "/home/ec2-user/intern_python/venv/lib64/python3.9/site-packages/django/utils/functional.py", line 57, in __get__
    res = instance.__dict__[self.name] = self.func(instance)
  File "/home/ec2-user/intern_python/venv/lib64/python3.9/site-packages/django/urls/resolvers.py", line 715, in url_patterns
    patterns = getattr(self.urlconf_module, "urlpatterns", self.urlconf_module)
  File "/home/ec2-user/intern_python/venv/lib64/python3.9/site-packages/django/utils/functional.py", line 57, in __get__
    res = instance.__dict__[self.name] = self.func(instance)
  File "/home/ec2-user/intern_python/venv/lib64/python3.9/site-packages/django/urls/resolvers.py", line 708, in urlconf_module
    return import_module(self.urlconf_name)
  File "/usr/lib64/python3.9/importlib/__init__.py", line 127, in import_module
    return _bootstrap._gcd_import(name[level:], package, level)
  File "<frozen importlib._bootstrap>", line 1030, in _gcd_import
  File "<frozen importlib._bootstrap>", line 1007, in _find_and_load
  File "<frozen importlib._bootstrap>", line 986, in _find_and_load_unlocked
  File "<frozen importlib._bootstrap>", line 680, in _load_unlocked
  File "<frozen importlib._bootstrap_external>", line 850, in exec_module
  File "<frozen importlib._bootstrap>", line 228, in _call_with_frames_removed
  File "/home/ec2-user/intern_python/python/urls.py", line 4, in <module>
    from drf_spectacular.views import SpectacularAPIView, SpectacularSwaggerView
  File "/home/ec2-user/intern_python/venv/lib64/python3.9/site-packages/drf_spectacular/views.py", line 44, in <module>
    class SpectacularAPIView(APIView):
  File "/home/ec2-user/intern_python/venv/lib64/python3.9/site-packages/drf_spectacular/views.py", line 64, in SpectacularAPIView
    def get(self, request, *args, **kwargs):
  File "/home/ec2-user/intern_python/venv/lib64/python3.9/site-packages/drf_spectacular/utils.py", line 430, in decorator
    or api_settings.DEFAULT_SCHEMA_CLASS
  File "/home/ec2-user/intern_python/venv/lib64/python3.9/site-packages/rest_framework/settings.py", line 227, in __getattr__
    val = perform_import(val, attr)
  File "/home/ec2-user/intern_python/venv/lib64/python3.9/site-packages/rest_framework/settings.py", line 168, in perform_import
    return import_from_string(val, setting_name)
  File "/home/ec2-user/intern_python/venv/lib64/python3.9/site-packages/rest_framework/settings.py", line 182, in import_from_string
    raise ImportError(msg)
ImportError: Could not import 'drf_spectacular.views.SpectacularAPIView' for API setting 'DEFAULT_SCHEMA_CLASS'. ImportError: Module "drf_spectacular.views" does not define a "SpectacularAPIView" attribute/class.

During handling of the above exception, another exception occurred:

Traceback (most recent call last):
  File "/home/ec2-user/intern_python/venv/lib64/python3.9/site-packages/django/utils/module_loading.py", line 30, in import_string
    return cached_import(module_path, class_name)
  File "/home/ec2-user/intern_python/venv/lib64/python3.9/site-packages/django/utils/module_loading.py", line 16, in cached_import
    return getattr(module, class_name)
AttributeError: partially initialized module 'drf_spectacular.views' has no attribute 'SpectacularAPIView' (most likely due to a circular import)

The above exception was the direct cause of the following exception:

Traceback (most recent call last):
  File "/home/ec2-user/intern_python/venv/lib64/python3.9/site-packages/rest_framework/settings.py", line 179, in import_from_string
    return import_string(val)
  File "/home/ec2-user/intern_python/venv/lib64/python3.9/site-packages/django/utils/module_loading.py", line 32, in import_string
    raise ImportError(
ImportError: Module "drf_spectacular.views" does not define a "SpectacularAPIView" attribute/class

During handling of the above exception, another exception occurred:

Traceback (most recent call last):
  File "/home/ec2-user/intern_python/venv/lib64/python3.9/site-packages/gunicorn/workers/sync.py", line 134, in handle
    self.handle_request(listener, req, client, addr)
  File "/home/ec2-user/intern_python/venv/lib64/python3.9/site-packages/gunicorn/workers/sync.py", line 177, in handle_request
    respiter = self.wsgi(environ, resp.start_response)
  File "/home/ec2-user/intern_python/venv/lib64/python3.9/site-packages/django/core/handlers/wsgi.py", line 124, in __call__
    response = self.get_response(request)
  File "/home/ec2-user/intern_python/venv/lib64/python3.9/site-packages/django/core/handlers/base.py", line 140, in get_response
    response = self._middleware_chain(request)
  File "/home/ec2-user/intern_python/venv/lib64/python3.9/site-packages/django/core/handlers/exception.py", line 57, in inner
    response = response_for_exception(request, exc)
  File "/home/ec2-user/intern_python/venv/lib64/python3.9/site-packages/django/core/handlers/exception.py", line 141, in response_for_exception
    response = handle_uncaught_exception(
  File "/home/ec2-user/intern_python/venv/lib64/python3.9/site-packages/django/core/handlers/exception.py", line 182, in handle_uncaught_exception
    return debug.technical_500_response(request, *exc_info)
  File "/home/ec2-user/intern_python/venv/lib64/python3.9/site-packages/django/views/debug.py", line 67, in technical_500_response
    html = reporter.get_traceback_html()
  File "/home/ec2-user/intern_python/venv/lib64/python3.9/site-packages/django/views/debug.py", line 410, in get_traceback_html
    c = Context(self.get_traceback_data(), use_l10n=False)
  File "/home/ec2-user/intern_python/venv/lib64/python3.9/site-packages/django/views/debug.py", line 393, in get_traceback_data
    c["raising_view_name"] = get_caller(self.request)
  File "/home/ec2-user/intern_python/venv/lib64/python3.9/site-packages/django/views/debug.py", line 100, in get_caller
    resolver_match = resolve(request.path)
  File "/home/ec2-user/intern_python/venv/lib64/python3.9/site-packages/django/urls/base.py", line 24, in resolve
    return get_resolver(urlconf).resolve(path)
  File "/home/ec2-user/intern_python/venv/lib64/python3.9/site-packages/django/urls/resolvers.py", line 663, in resolve
    for pattern in self.url_patterns:
  File "/home/ec2-user/intern_python/venv/lib64/python3.9/site-packages/django/utils/functional.py", line 57, in __get__
    res = instance.__dict__[self.name] = self.func(instance)
  File "/home/ec2-user/intern_python/venv/lib64/python3.9/site-packages/django/urls/resolvers.py", line 715, in url_patterns
    patterns = getattr(self.urlconf_module, "urlpatterns", self.urlconf_module)
  File "/home/ec2-user/intern_python/venv/lib64/python3.9/site-packages/django/utils/functional.py", line 57, in __get__
    res = instance.__dict__[self.name] = self.func(instance)
  File "/home/ec2-user/intern_python/venv/lib64/python3.9/site-packages/django/urls/resolvers.py", line 708, in urlconf_module
    return import_module(self.urlconf_name)
  File "/usr/lib64/python3.9/importlib/__init__.py", line 127, in import_module
    return _bootstrap._gcd_import(name[level:], package, level)
  File "<frozen importlib._bootstrap>", line 1030, in _gcd_import
  File "<frozen importlib._bootstrap>", line 1007, in _find_and_load
  File "<frozen importlib._bootstrap>", line 986, in _find_and_load_unlocked
  File "<frozen importlib._bootstrap>", line 680, in _load_unlocked
  File "<frozen importlib._bootstrap_external>", line 850, in exec_module
  File "<frozen importlib._bootstrap>", line 228, in _call_with_frames_removed
  File "/home/ec2-user/intern_python/python/urls.py", line 4, in <module>
    from drf_spectacular.views import SpectacularAPIView, SpectacularSwaggerView
  File "/home/ec2-user/intern_python/venv/lib64/python3.9/site-packages/drf_spectacular/views.py", line 44, in <module>
    class SpectacularAPIView(APIView):
  File "/home/ec2-user/intern_python/venv/lib64/python3.9/site-packages/drf_spectacular/views.py", line 64, in SpectacularAPIView
    def get(self, request, *args, **kwargs):
  File "/home/ec2-user/intern_python/venv/lib64/python3.9/site-packages/drf_spectacular/utils.py", line 430, in decorator
    or api_settings.DEFAULT_SCHEMA_CLASS
  File "/home/ec2-user/intern_python/venv/lib64/python3.9/site-packages/rest_framework/settings.py", line 227, in __getattr__
    val = perform_import(val, attr)
  File "/home/ec2-user/intern_python/venv/lib64/python3.9/site-packages/rest_framework/settings.py", line 168, in perform_import
    return import_from_string(val, setting_name)
  File "/home/ec2-user/intern_python/venv/lib64/python3.9/site-packages/rest_framework/settings.py", line 182, in import_from_string
    raise ImportError(msg)
ImportError: Could not import 'drf_spectacular.views.SpectacularAPIView' for API setting 'DEFAULT_SCHEMA_CLASS'. ImportError: Module "drf_spectacular.views" does not define a "SpectacularAPIView" attribute/class.
[2025-06-14 07:17:34 +0000] [28062] [ERROR] Error handling request /swagger/
Traceback (most recent call last):
  File "/home/ec2-user/intern_python/venv/lib64/python3.9/site-packages/django/utils/module_loading.py", line 30, in import_string
    return cached_import(module_path, class_name)
  File "/home/ec2-user/intern_python/venv/lib64/python3.9/site-packages/django/utils/module_loading.py", line 16, in cached_import
    return getattr(module, class_name)
AttributeError: partially initialized module 'drf_spectacular.views' has no attribute 'SpectacularAPIView' (most likely due to a circular import)

The above exception was the direct cause of the following exception:

Traceback (most recent call last):
  File "/home/ec2-user/intern_python/venv/lib64/python3.9/site-packages/rest_framework/settings.py", line 179, in import_from_string
    return import_string(val)
  File "/home/ec2-user/intern_python/venv/lib64/python3.9/site-packages/django/utils/module_loading.py", line 32, in import_string
    raise ImportError(
ImportError: Module "drf_spectacular.views" does not define a "SpectacularAPIView" attribute/class

During handling of the above exception, another exception occurred:

Traceback (most recent call last):
  File "/home/ec2-user/intern_python/venv/lib64/python3.9/site-packages/django/core/handlers/exception.py", line 55, in inner
    response = get_response(request)
  File "/home/ec2-user/intern_python/venv/lib64/python3.9/site-packages/django/core/handlers/base.py", line 181, in _get_response
    callback, callback_args, callback_kwargs = self.resolve_request(request)
  File "/home/ec2-user/intern_python/venv/lib64/python3.9/site-packages/django/core/handlers/base.py", line 313, in resolve_request
    resolver_match = resolver.resolve(request.path_info)
  File "/home/ec2-user/intern_python/venv/lib64/python3.9/site-packages/django/urls/resolvers.py", line 663, in resolve
    for pattern in self.url_patterns:
  File "/home/ec2-user/intern_python/venv/lib64/python3.9/site-packages/django/utils/functional.py", line 57, in __get__
    res = instance.__dict__[self.name] = self.func(instance)
  File "/home/ec2-user/intern_python/venv/lib64/python3.9/site-packages/django/urls/resolvers.py", line 715, in url_patterns
    patterns = getattr(self.urlconf_module, "urlpatterns", self.urlconf_module)
  File "/home/ec2-user/intern_python/venv/lib64/python3.9/site-packages/django/utils/functional.py", line 57, in __get__
    res = instance.__dict__[self.name] = self.func(instance)
  File "/home/ec2-user/intern_python/venv/lib64/python3.9/site-packages/django/urls/resolvers.py", line 708, in urlconf_module
    return import_module(self.urlconf_name)
  File "/usr/lib64/python3.9/importlib/__init__.py", line 127, in import_module
    return _bootstrap._gcd_import(name[level:], package, level)
  File "<frozen importlib._bootstrap>", line 1030, in _gcd_import
  File "<frozen importlib._bootstrap>", line 1007, in _find_and_load
  File "<frozen importlib._bootstrap>", line 986, in _find_and_load_unlocked
  File "<frozen importlib._bootstrap>", line 680, in _load_unlocked
  File "<frozen importlib._bootstrap_external>", line 850, in exec_module
  File "<frozen importlib._bootstrap>", line 228, in _call_with_frames_removed
  File "/home/ec2-user/intern_python/python/urls.py", line 4, in <module>
    from drf_spectacular.views import SpectacularAPIView, SpectacularSwaggerView
  File "/home/ec2-user/intern_python/venv/lib64/python3.9/site-packages/drf_spectacular/views.py", line 44, in <module>
    class SpectacularAPIView(APIView):
  File "/home/ec2-user/intern_python/venv/lib64/python3.9/site-packages/drf_spectacular/views.py", line 64, in SpectacularAPIView
    def get(self, request, *args, **kwargs):
  File "/home/ec2-user/intern_python/venv/lib64/python3.9/site-packages/drf_spectacular/utils.py", line 430, in decorator
    or api_settings.DEFAULT_SCHEMA_CLASS
  File "/home/ec2-user/intern_python/venv/lib64/python3.9/site-packages/rest_framework/settings.py", line 227, in __getattr__
    val = perform_import(val, attr)
  File "/home/ec2-user/intern_python/venv/lib64/python3.9/site-packages/rest_framework/settings.py", line 168, in perform_import
    return import_from_string(val, setting_name)
  File "/home/ec2-user/intern_python/venv/lib64/python3.9/site-packages/rest_framework/settings.py", line 182, in import_from_string
    raise ImportError(msg)
ImportError: Could not import 'drf_spectacular.views.SpectacularAPIView' for API setting 'DEFAULT_SCHEMA_CLASS'. ImportError: Module "drf_spectacular.views" does not define a "SpectacularAPIView" attribute/class.

During handling of the above exception, another exception occurred:

Traceback (most recent call last):
  File "/home/ec2-user/intern_python/venv/lib64/python3.9/site-packages/django/utils/module_loading.py", line 30, in import_string
    return cached_import(module_path, class_name)
  File "/home/ec2-user/intern_python/venv/lib64/python3.9/site-packages/django/utils/module_loading.py", line 16, in cached_import
    return getattr(module, class_name)
AttributeError: partially initialized module 'drf_spectacular.views' has no attribute 'SpectacularAPIView' (most likely due to a circular import)

The above exception was the direct cause of the following exception:

Traceback (most recent call last):
  File "/home/ec2-user/intern_python/venv/lib64/python3.9/site-packages/rest_framework/settings.py", line 179, in import_from_string
    return import_string(val)
  File "/home/ec2-user/intern_python/venv/lib64/python3.9/site-packages/django/utils/module_loading.py", line 32, in import_string
    raise ImportError(
ImportError: Module "drf_spectacular.views" does not define a "SpectacularAPIView" attribute/class

During handling of the above exception, another exception occurred:

Traceback (most recent call last):
  File "/home/ec2-user/intern_python/venv/lib64/python3.9/site-packages/django/core/handlers/exception.py", line 55, in inner
    response = get_response(request)
  File "/home/ec2-user/intern_python/venv/lib64/python3.9/site-packages/django/utils/deprecation.py", line 134, in __call__
    response = response or self.get_response(request)
  File "/home/ec2-user/intern_python/venv/lib64/python3.9/site-packages/django/core/handlers/exception.py", line 57, in inner
    response = response_for_exception(request, exc)
  File "/home/ec2-user/intern_python/venv/lib64/python3.9/site-packages/django/core/handlers/exception.py", line 141, in response_for_exception
    response = handle_uncaught_exception(
  File "/home/ec2-user/intern_python/venv/lib64/python3.9/site-packages/django/core/handlers/exception.py", line 182, in handle_uncaught_exception
    return debug.technical_500_response(request, *exc_info)
  File "/home/ec2-user/intern_python/venv/lib64/python3.9/site-packages/django/views/debug.py", line 67, in technical_500_response
    html = reporter.get_traceback_html()
  File "/home/ec2-user/intern_python/venv/lib64/python3.9/site-packages/django/views/debug.py", line 410, in get_traceback_html
    c = Context(self.get_traceback_data(), use_l10n=False)
  File "/home/ec2-user/intern_python/venv/lib64/python3.9/site-packages/django/views/debug.py", line 393, in get_traceback_data
    c["raising_view_name"] = get_caller(self.request)
  File "/home/ec2-user/intern_python/venv/lib64/python3.9/site-packages/django/views/debug.py", line 100, in get_caller
    resolver_match = resolve(request.path)
  File "/home/ec2-user/intern_python/venv/lib64/python3.9/site-packages/django/urls/base.py", line 24, in resolve
    return get_resolver(urlconf).resolve(path)
  File "/home/ec2-user/intern_python/venv/lib64/python3.9/site-packages/django/urls/resolvers.py", line 663, in resolve
    for pattern in self.url_patterns:
  File "/home/ec2-user/intern_python/venv/lib64/python3.9/site-packages/django/utils/functional.py", line 57, in __get__
    res = instance.__dict__[self.name] = self.func(instance)
  File "/home/ec2-user/intern_python/venv/lib64/python3.9/site-packages/django/urls/resolvers.py", line 715, in url_patterns
    patterns = getattr(self.urlconf_module, "urlpatterns", self.urlconf_module)
  File "/home/ec2-user/intern_python/venv/lib64/python3.9/site-packages/django/utils/functional.py", line 57, in __get__
    res = instance.__dict__[self.name] = self.func(instance)
  File "/home/ec2-user/intern_python/venv/lib64/python3.9/site-packages/django/urls/resolvers.py", line 708, in urlconf_module
    return import_module(self.urlconf_name)
  File "/usr/lib64/python3.9/importlib/__init__.py", line 127, in import_module
    return _bootstrap._gcd_import(name[level:], package, level)
  File "<frozen importlib._bootstrap>", line 1030, in _gcd_import
  File "<frozen importlib._bootstrap>", line 1007, in _find_and_load
  File "<frozen importlib._bootstrap>", line 986, in _find_and_load_unlocked
  File "<frozen importlib._bootstrap>", line 680, in _load_unlocked
  File "<frozen importlib._bootstrap_external>", line 850, in exec_module
  File "<frozen importlib._bootstrap>", line 228, in _call_with_frames_removed
  File "/home/ec2-user/intern_python/python/urls.py", line 4, in <module>
    from drf_spectacular.views import SpectacularAPIView, SpectacularSwaggerView
  File "/home/ec2-user/intern_python/venv/lib64/python3.9/site-packages/drf_spectacular/views.py", line 44, in <module>
    class SpectacularAPIView(APIView):
  File "/home/ec2-user/intern_python/venv/lib64/python3.9/site-packages/drf_spectacular/views.py", line 64, in SpectacularAPIView
    def get(self, request, *args, **kwargs):
  File "/home/ec2-user/intern_python/venv/lib64/python3.9/site-packages/drf_spectacular/utils.py", line 430, in decorator
    or api_settings.DEFAULT_SCHEMA_CLASS
  File "/home/ec2-user/intern_python/venv/lib64/python3.9/site-packages/rest_framework/settings.py", line 227, in __getattr__
    val = perform_import(val, attr)
  File "/home/ec2-user/intern_python/venv/lib64/python3.9/site-packages/rest_framework/settings.py", line 168, in perform_import
    return import_from_string(val, setting_name)
  File "/home/ec2-user/intern_python/venv/lib64/python3.9/site-packages/rest_framework/settings.py", line 182, in import_from_string
    raise ImportError(msg)
ImportError: Could not import 'drf_spectacular.views.SpectacularAPIView' for API setting 'DEFAULT_SCHEMA_CLASS'. ImportError: Module "drf_spectacular.views" does not define a "SpectacularAPIView" attribute/class.

During handling of the above exception, another exception occurred:

Traceback (most recent call last):
  File "/home/ec2-user/intern_python/venv/lib64/python3.9/site-packages/django/utils/module_loading.py", line 30, in import_string
    return cached_import(module_path, class_name)
  File "/home/ec2-user/intern_python/venv/lib64/python3.9/site-packages/django/utils/module_loading.py", line 16, in cached_import
    return getattr(module, class_name)
AttributeError: partially initialized module 'drf_spectacular.views' has no attribute 'SpectacularAPIView' (most likely due to a circular import)

The above exception was the direct cause of the following exception:

Traceback (most recent call last):
  File "/home/ec2-user/intern_python/venv/lib64/python3.9/site-packages/rest_framework/settings.py", line 179, in import_from_string
    return import_string(val)
  File "/home/ec2-user/intern_python/venv/lib64/python3.9/site-packages/django/utils/module_loading.py", line 32, in import_string
    raise ImportError(
ImportError: Module "drf_spectacular.views" does not define a "SpectacularAPIView" attribute/class

During handling of the above exception, another exception occurred:

Traceback (most recent call last):
  File "/home/ec2-user/intern_python/venv/lib64/python3.9/site-packages/django/core/handlers/exception.py", line 55, in inner
    response = get_response(request)
  File "/home/ec2-user/intern_python/venv/lib64/python3.9/site-packages/django/utils/deprecation.py", line 134, in __call__
    response = response or self.get_response(request)
  File "/home/ec2-user/intern_python/venv/lib64/python3.9/site-packages/django/core/handlers/exception.py", line 57, in inner
    response = response_for_exception(request, exc)
  File "/home/ec2-user/intern_python/venv/lib64/python3.9/site-packages/django/core/handlers/exception.py", line 141, in response_for_exception
    response = handle_uncaught_exception(
  File "/home/ec2-user/intern_python/venv/lib64/python3.9/site-packages/django/core/handlers/exception.py", line 182, in handle_uncaught_exception
    return debug.technical_500_response(request, *exc_info)
  File "/home/ec2-user/intern_python/venv/lib64/python3.9/site-packages/django/views/debug.py", line 67, in technical_500_response
    html = reporter.get_traceback_html()
  File "/home/ec2-user/intern_python/venv/lib64/python3.9/site-packages/django/views/debug.py", line 410, in get_traceback_html
    c = Context(self.get_traceback_data(), use_l10n=False)
  File "/home/ec2-user/intern_python/venv/lib64/python3.9/site-packages/django/views/debug.py", line 393, in get_traceback_data
    c["raising_view_name"] = get_caller(self.request)
  File "/home/ec2-user/intern_python/venv/lib64/python3.9/site-packages/django/views/debug.py", line 100, in get_caller
    resolver_match = resolve(request.path)
  File "/home/ec2-user/intern_python/venv/lib64/python3.9/site-packages/django/urls/base.py", line 24, in resolve
    return get_resolver(urlconf).resolve(path)
  File "/home/ec2-user/intern_python/venv/lib64/python3.9/site-packages/django/urls/resolvers.py", line 663, in resolve
    for pattern in self.url_patterns:
  File "/home/ec2-user/intern_python/venv/lib64/python3.9/site-packages/django/utils/functional.py", line 57, in __get__
    res = instance.__dict__[self.name] = self.func(instance)
  File "/home/ec2-user/intern_python/venv/lib64/python3.9/site-packages/django/urls/resolvers.py", line 715, in url_patterns
    patterns = getattr(self.urlconf_module, "urlpatterns", self.urlconf_module)
  File "/home/ec2-user/intern_python/venv/lib64/python3.9/site-packages/django/utils/functional.py", line 57, in __get__
    res = instance.__dict__[self.name] = self.func(instance)
  File "/home/ec2-user/intern_python/venv/lib64/python3.9/site-packages/django/urls/resolvers.py", line 708, in urlconf_module
    return import_module(self.urlconf_name)
  File "/usr/lib64/python3.9/importlib/__init__.py", line 127, in import_module
    return _bootstrap._gcd_import(name[level:], package, level)
  File "<frozen importlib._bootstrap>", line 1030, in _gcd_import
  File "<frozen importlib._bootstrap>", line 1007, in _find_and_load
  File "<frozen importlib._bootstrap>", line 986, in _find_and_load_unlocked
  File "<frozen importlib._bootstrap>", line 680, in _load_unlocked
  File "<frozen importlib._bootstrap_external>", line 850, in exec_module
  File "<frozen importlib._bootstrap>", line 228, in _call_with_frames_removed
  File "/home/ec2-user/intern_python/python/urls.py", line 4, in <module>
    from drf_spectacular.views import SpectacularAPIView, SpectacularSwaggerView
  File "/home/ec2-user/intern_python/venv/lib64/python3.9/site-packages/drf_spectacular/views.py", line 44, in <module>
    class SpectacularAPIView(APIView):
  File "/home/ec2-user/intern_python/venv/lib64/python3.9/site-packages/drf_spectacular/views.py", line 64, in SpectacularAPIView
    def get(self, request, *args, **kwargs):
  File "/home/ec2-user/intern_python/venv/lib64/python3.9/site-packages/drf_spectacular/utils.py", line 430, in decorator
    or api_settings.DEFAULT_SCHEMA_CLASS
  File "/home/ec2-user/intern_python/venv/lib64/python3.9/site-packages/rest_framework/settings.py", line 227, in __getattr__
    val = perform_import(val, attr)
  File "/home/ec2-user/intern_python/venv/lib64/python3.9/site-packages/rest_framework/settings.py", line 168, in perform_import
    return import_from_string(val, setting_name)
  File "/home/ec2-user/intern_python/venv/lib64/python3.9/site-packages/rest_framework/settings.py", line 182, in import_from_string
    raise ImportError(msg)
ImportError: Could not import 'drf_spectacular.views.SpectacularAPIView' for API setting 'DEFAULT_SCHEMA_CLASS'. ImportError: Module "drf_spectacular.views" does not define a "SpectacularAPIView" attribute/class.

During handling of the above exception, another exception occurred:

Traceback (most recent call last):
  File "/home/ec2-user/intern_python/venv/lib64/python3.9/site-packages/django/utils/module_loading.py", line 30, in import_string
    return cached_import(module_path, class_name)
  File "/home/ec2-user/intern_python/venv/lib64/python3.9/site-packages/django/utils/module_loading.py", line 16, in cached_import
    return getattr(module, class_name)
AttributeError: partially initialized module 'drf_spectacular.views' has no attribute 'SpectacularAPIView' (most likely due to a circular import)

The above exception was the direct cause of the following exception:

Traceback (most recent call last):
  File "/home/ec2-user/intern_python/venv/lib64/python3.9/site-packages/rest_framework/settings.py", line 179, in import_from_string
    return import_string(val)
  File "/home/ec2-user/intern_python/venv/lib64/python3.9/site-packages/django/utils/module_loading.py", line 32, in import_string
    raise ImportError(
ImportError: Module "drf_spectacular.views" does not define a "SpectacularAPIView" attribute/class

During handling of the above exception, another exception occurred:

Traceback (most recent call last):
  File "/home/ec2-user/intern_python/venv/lib64/python3.9/site-packages/django/core/handlers/exception.py", line 55, in inner
    response = get_response(request)
  File "/home/ec2-user/intern_python/venv/lib64/python3.9/site-packages/django/utils/deprecation.py", line 134, in __call__
    response = response or self.get_response(request)
  File "/home/ec2-user/intern_python/venv/lib64/python3.9/site-packages/django/core/handlers/exception.py", line 57, in inner
    response = response_for_exception(request, exc)
  File "/home/ec2-user/intern_python/venv/lib64/python3.9/site-packages/django/core/handlers/exception.py", line 141, in response_for_exception
    response = handle_uncaught_exception(
  File "/home/ec2-user/intern_python/venv/lib64/python3.9/site-packages/django/core/handlers/exception.py", line 182, in handle_uncaught_exception
    return debug.technical_500_response(request, *exc_info)
  File "/home/ec2-user/intern_python/venv/lib64/python3.9/site-packages/django/views/debug.py", line 67, in technical_500_response
    html = reporter.get_traceback_html()
  File "/home/ec2-user/intern_python/venv/lib64/python3.9/site-packages/django/views/debug.py", line 410, in get_traceback_html
    c = Context(self.get_traceback_data(), use_l10n=False)
  File "/home/ec2-user/intern_python/venv/lib64/python3.9/site-packages/django/views/debug.py", line 393, in get_traceback_data
    c["raising_view_name"] = get_caller(self.request)
  File "/home/ec2-user/intern_python/venv/lib64/python3.9/site-packages/django/views/debug.py", line 100, in get_caller
    resolver_match = resolve(request.path)
  File "/home/ec2-user/intern_python/venv/lib64/python3.9/site-packages/django/urls/base.py", line 24, in resolve
    return get_resolver(urlconf).resolve(path)
  File "/home/ec2-user/intern_python/venv/lib64/python3.9/site-packages/django/urls/resolvers.py", line 663, in resolve
    for pattern in self.url_patterns:
  File "/home/ec2-user/intern_python/venv/lib64/python3.9/site-packages/django/utils/functional.py", line 57, in __get__
    res = instance.__dict__[self.name] = self.func(instance)
  File "/home/ec2-user/intern_python/venv/lib64/python3.9/site-packages/django/urls/resolvers.py", line 715, in url_patterns
    patterns = getattr(self.urlconf_module, "urlpatterns", self.urlconf_module)
  File "/home/ec2-user/intern_python/venv/lib64/python3.9/site-packages/django/utils/functional.py", line 57, in __get__
    res = instance.__dict__[self.name] = self.func(instance)
  File "/home/ec2-user/intern_python/venv/lib64/python3.9/site-packages/django/urls/resolvers.py", line 708, in urlconf_module
    return import_module(self.urlconf_name)
  File "/usr/lib64/python3.9/importlib/__init__.py", line 127, in import_module
    return _bootstrap._gcd_import(name[level:], package, level)
  File "<frozen importlib._bootstrap>", line 1030, in _gcd_import
  File "<frozen importlib._bootstrap>", line 1007, in _find_and_load
  File "<frozen importlib._bootstrap>", line 986, in _find_and_load_unlocked
  File "<frozen importlib._bootstrap>", line 680, in _load_unlocked
  File "<frozen importlib._bootstrap_external>", line 850, in exec_module
  File "<frozen importlib._bootstrap>", line 228, in _call_with_frames_removed
  File "/home/ec2-user/intern_python/python/urls.py", line 4, in <module>
    from drf_spectacular.views import SpectacularAPIView, SpectacularSwaggerView
  File "/home/ec2-user/intern_python/venv/lib64/python3.9/site-packages/drf_spectacular/views.py", line 44, in <module>
    class SpectacularAPIView(APIView):
  File "/home/ec2-user/intern_python/venv/lib64/python3.9/site-packages/drf_spectacular/views.py", line 64, in SpectacularAPIView
    def get(self, request, *args, **kwargs):
  File "/home/ec2-user/intern_python/venv/lib64/python3.9/site-packages/drf_spectacular/utils.py", line 430, in decorator
    or api_settings.DEFAULT_SCHEMA_CLASS
  File "/home/ec2-user/intern_python/venv/lib64/python3.9/site-packages/rest_framework/settings.py", line 227, in __getattr__
    val = perform_import(val, attr)
  File "/home/ec2-user/intern_python/venv/lib64/python3.9/site-packages/rest_framework/settings.py", line 168, in perform_import
    return import_from_string(val, setting_name)
  File "/home/ec2-user/intern_python/venv/lib64/python3.9/site-packages/rest_framework/settings.py", line 182, in import_from_string
    raise ImportError(msg)
ImportError: Could not import 'drf_spectacular.views.SpectacularAPIView' for API setting 'DEFAULT_SCHEMA_CLASS'. ImportError: Module "drf_spectacular.views" does not define a "SpectacularAPIView" attribute/class.

During handling of the above exception, another exception occurred:

Traceback (most recent call last):
  File "/home/ec2-user/intern_python/venv/lib64/python3.9/site-packages/django/utils/module_loading.py", line 30, in import_string
    return cached_import(module_path, class_name)
  File "/home/ec2-user/intern_python/venv/lib64/python3.9/site-packages/django/utils/module_loading.py", line 16, in cached_import
    return getattr(module, class_name)
AttributeError: partially initialized module 'drf_spectacular.views' has no attribute 'SpectacularAPIView' (most likely due to a circular import)

The above exception was the direct cause of the following exception:

Traceback (most recent call last):
  File "/home/ec2-user/intern_python/venv/lib64/python3.9/site-packages/rest_framework/settings.py", line 179, in import_from_string
    return import_string(val)
  File "/home/ec2-user/intern_python/venv/lib64/python3.9/site-packages/django/utils/module_loading.py", line 32, in import_string
    raise ImportError(
ImportError: Module "drf_spectacular.views" does not define a "SpectacularAPIView" attribute/class

During handling of the above exception, another exception occurred:

Traceback (most recent call last):
  File "/home/ec2-user/intern_python/venv/lib64/python3.9/site-packages/django/core/handlers/exception.py", line 55, in inner
    response = get_response(request)
  File "/home/ec2-user/intern_python/venv/lib64/python3.9/site-packages/django/utils/deprecation.py", line 134, in __call__
    response = response or self.get_response(request)
  File "/home/ec2-user/intern_python/venv/lib64/python3.9/site-packages/django/core/handlers/exception.py", line 57, in inner
    response = response_for_exception(request, exc)
  File "/home/ec2-user/intern_python/venv/lib64/python3.9/site-packages/django/core/handlers/exception.py", line 141, in response_for_exception
    response = handle_uncaught_exception(
  File "/home/ec2-user/intern_python/venv/lib64/python3.9/site-packages/django/core/handlers/exception.py", line 182, in handle_uncaught_exception
    return debug.technical_500_response(request, *exc_info)
  File "/home/ec2-user/intern_python/venv/lib64/python3.9/site-packages/django/views/debug.py", line 67, in technical_500_response
    html = reporter.get_traceback_html()
  File "/home/ec2-user/intern_python/venv/lib64/python3.9/site-packages/django/views/debug.py", line 410, in get_traceback_html
    c = Context(self.get_traceback_data(), use_l10n=False)
  File "/home/ec2-user/intern_python/venv/lib64/python3.9/site-packages/django/views/debug.py", line 393, in get_traceback_data
    c["raising_view_name"] = get_caller(self.request)
  File "/home/ec2-user/intern_python/venv/lib64/python3.9/site-packages/django/views/debug.py", line 100, in get_caller
    resolver_match = resolve(request.path)
  File "/home/ec2-user/intern_python/venv/lib64/python3.9/site-packages/django/urls/base.py", line 24, in resolve
    return get_resolver(urlconf).resolve(path)
  File "/home/ec2-user/intern_python/venv/lib64/python3.9/site-packages/django/urls/resolvers.py", line 663, in resolve
    for pattern in self.url_patterns:
  File "/home/ec2-user/intern_python/venv/lib64/python3.9/site-packages/django/utils/functional.py", line 57, in __get__
    res = instance.__dict__[self.name] = self.func(instance)
  File "/home/ec2-user/intern_python/venv/lib64/python3.9/site-packages/django/urls/resolvers.py", line 715, in url_patterns
    patterns = getattr(self.urlconf_module, "urlpatterns", self.urlconf_module)
  File "/home/ec2-user/intern_python/venv/lib64/python3.9/site-packages/django/utils/functional.py", line 57, in __get__
    res = instance.__dict__[self.name] = self.func(instance)
  File "/home/ec2-user/intern_python/venv/lib64/python3.9/site-packages/django/urls/resolvers.py", line 708, in urlconf_module
    return import_module(self.urlconf_name)
  File "/usr/lib64/python3.9/importlib/__init__.py", line 127, in import_module
    return _bootstrap._gcd_import(name[level:], package, level)
  File "<frozen importlib._bootstrap>", line 1030, in _gcd_import
  File "<frozen importlib._bootstrap>", line 1007, in _find_and_load
  File "<frozen importlib._bootstrap>", line 986, in _find_and_load_unlocked
  File "<frozen importlib._bootstrap>", line 680, in _load_unlocked
  File "<frozen importlib._bootstrap_external>", line 850, in exec_module
  File "<frozen importlib._bootstrap>", line 228, in _call_with_frames_removed
  File "/home/ec2-user/intern_python/python/urls.py", line 4, in <module>
    from drf_spectacular.views import SpectacularAPIView, SpectacularSwaggerView
  File "/home/ec2-user/intern_python/venv/lib64/python3.9/site-packages/drf_spectacular/views.py", line 44, in <module>
    class SpectacularAPIView(APIView):
  File "/home/ec2-user/intern_python/venv/lib64/python3.9/site-packages/drf_spectacular/views.py", line 64, in SpectacularAPIView
    def get(self, request, *args, **kwargs):
  File "/home/ec2-user/intern_python/venv/lib64/python3.9/site-packages/drf_spectacular/utils.py", line 430, in decorator
    or api_settings.DEFAULT_SCHEMA_CLASS
  File "/home/ec2-user/intern_python/venv/lib64/python3.9/site-packages/rest_framework/settings.py", line 227, in __getattr__
    val = perform_import(val, attr)
  File "/home/ec2-user/intern_python/venv/lib64/python3.9/site-packages/rest_framework/settings.py", line 168, in perform_import
    return import_from_string(val, setting_name)
  File "/home/ec2-user/intern_python/venv/lib64/python3.9/site-packages/rest_framework/settings.py", line 182, in import_from_string
    raise ImportError(msg)
ImportError: Could not import 'drf_spectacular.views.SpectacularAPIView' for API setting 'DEFAULT_SCHEMA_CLASS'. ImportError: Module "drf_spectacular.views" does not define a "SpectacularAPIView" attribute/class.

During handling of the above exception, another exception occurred:

Traceback (most recent call last):
  File "/home/ec2-user/intern_python/venv/lib64/python3.9/site-packages/django/utils/module_loading.py", line 30, in import_string
    return cached_import(module_path, class_name)
  File "/home/ec2-user/intern_python/venv/lib64/python3.9/site-packages/django/utils/module_loading.py", line 16, in cached_import
    return getattr(module, class_name)
AttributeError: partially initialized module 'drf_spectacular.views' has no attribute 'SpectacularAPIView' (most likely due to a circular import)

The above exception was the direct cause of the following exception:

Traceback (most recent call last):
  File "/home/ec2-user/intern_python/venv/lib64/python3.9/site-packages/rest_framework/settings.py", line 179, in import_from_string
    return import_string(val)
  File "/home/ec2-user/intern_python/venv/lib64/python3.9/site-packages/django/utils/module_loading.py", line 32, in import_string
    raise ImportError(
ImportError: Module "drf_spectacular.views" does not define a "SpectacularAPIView" attribute/class

During handling of the above exception, another exception occurred:

Traceback (most recent call last):
  File "/home/ec2-user/intern_python/venv/lib64/python3.9/site-packages/django/core/handlers/exception.py", line 55, in inner
    response = get_response(request)
  File "/home/ec2-user/intern_python/venv/lib64/python3.9/site-packages/django/utils/deprecation.py", line 134, in __call__
    response = response or self.get_response(request)
  File "/home/ec2-user/intern_python/venv/lib64/python3.9/site-packages/django/core/handlers/exception.py", line 57, in inner
    response = response_for_exception(request, exc)
  File "/home/ec2-user/intern_python/venv/lib64/python3.9/site-packages/django/core/handlers/exception.py", line 141, in response_for_exception
    response = handle_uncaught_exception(
  File "/home/ec2-user/intern_python/venv/lib64/python3.9/site-packages/django/core/handlers/exception.py", line 182, in handle_uncaught_exception
    return debug.technical_500_response(request, *exc_info)
  File "/home/ec2-user/intern_python/venv/lib64/python3.9/site-packages/django/views/debug.py", line 67, in technical_500_response
    html = reporter.get_traceback_html()
  File "/home/ec2-user/intern_python/venv/lib64/python3.9/site-packages/django/views/debug.py", line 410, in get_traceback_html
    c = Context(self.get_traceback_data(), use_l10n=False)
  File "/home/ec2-user/intern_python/venv/lib64/python3.9/site-packages/django/views/debug.py", line 393, in get_traceback_data
    c["raising_view_name"] = get_caller(self.request)
  File "/home/ec2-user/intern_python/venv/lib64/python3.9/site-packages/django/views/debug.py", line 100, in get_caller
    resolver_match = resolve(request.path)
  File "/home/ec2-user/intern_python/venv/lib64/python3.9/site-packages/django/urls/base.py", line 24, in resolve
    return get_resolver(urlconf).resolve(path)
  File "/home/ec2-user/intern_python/venv/lib64/python3.9/site-packages/django/urls/resolvers.py", line 663, in resolve
    for pattern in self.url_patterns:
  File "/home/ec2-user/intern_python/venv/lib64/python3.9/site-packages/django/utils/functional.py", line 57, in __get__
    res = instance.__dict__[self.name] = self.func(instance)
  File "/home/ec2-user/intern_python/venv/lib64/python3.9/site-packages/django/urls/resolvers.py", line 715, in url_patterns
    patterns = getattr(self.urlconf_module, "urlpatterns", self.urlconf_module)
  File "/home/ec2-user/intern_python/venv/lib64/python3.9/site-packages/django/utils/functional.py", line 57, in __get__
    res = instance.__dict__[self.name] = self.func(instance)
  File "/home/ec2-user/intern_python/venv/lib64/python3.9/site-packages/django/urls/resolvers.py", line 708, in urlconf_module
    return import_module(self.urlconf_name)
  File "/usr/lib64/python3.9/importlib/__init__.py", line 127, in import_module
    return _bootstrap._gcd_import(name[level:], package, level)
  File "<frozen importlib._bootstrap>", line 1030, in _gcd_import
  File "<frozen importlib._bootstrap>", line 1007, in _find_and_load
  File "<frozen importlib._bootstrap>", line 986, in _find_and_load_unlocked
  File "<frozen importlib._bootstrap>", line 680, in _load_unlocked
  File "<frozen importlib._bootstrap_external>", line 850, in exec_module
  File "<frozen importlib._bootstrap>", line 228, in _call_with_frames_removed
  File "/home/ec2-user/intern_python/python/urls.py", line 4, in <module>
    from drf_spectacular.views import SpectacularAPIView, SpectacularSwaggerView
  File "/home/ec2-user/intern_python/venv/lib64/python3.9/site-packages/drf_spectacular/views.py", line 44, in <module>
    class SpectacularAPIView(APIView):
  File "/home/ec2-user/intern_python/venv/lib64/python3.9/site-packages/drf_spectacular/views.py", line 64, in SpectacularAPIView
    def get(self, request, *args, **kwargs):
  File "/home/ec2-user/intern_python/venv/lib64/python3.9/site-packages/drf_spectacular/utils.py", line 430, in decorator
    or api_settings.DEFAULT_SCHEMA_CLASS
  File "/home/ec2-user/intern_python/venv/lib64/python3.9/site-packages/rest_framework/settings.py", line 227, in __getattr__
    val = perform_import(val, attr)
  File "/home/ec2-user/intern_python/venv/lib64/python3.9/site-packages/rest_framework/settings.py", line 168, in perform_import
    return import_from_string(val, setting_name)
  File "/home/ec2-user/intern_python/venv/lib64/python3.9/site-packages/rest_framework/settings.py", line 182, in import_from_string
    raise ImportError(msg)
ImportError: Could not import 'drf_spectacular.views.SpectacularAPIView' for API setting 'DEFAULT_SCHEMA_CLASS'. ImportError: Module "drf_spectacular.views" does not define a "SpectacularAPIView" attribute/class.

During handling of the above exception, another exception occurred:

Traceback (most recent call last):
  File "/home/ec2-user/intern_python/venv/lib64/python3.9/site-packages/django/utils/module_loading.py", line 30, in import_string
    return cached_import(module_path, class_name)
  File "/home/ec2-user/intern_python/venv/lib64/python3.9/site-packages/django/utils/module_loading.py", line 16, in cached_import
    return getattr(module, class_name)
AttributeError: partially initialized module 'drf_spectacular.views' has no attribute 'SpectacularAPIView' (most likely due to a circular import)

The above exception was the direct cause of the following exception:

Traceback (most recent call last):
  File "/home/ec2-user/intern_python/venv/lib64/python3.9/site-packages/rest_framework/settings.py", line 179, in import_from_string
    return import_string(val)
  File "/home/ec2-user/intern_python/venv/lib64/python3.9/site-packages/django/utils/module_loading.py", line 32, in import_string
    raise ImportError(
ImportError: Module "drf_spectacular.views" does not define a "SpectacularAPIView" attribute/class

During handling of the above exception, another exception occurred:

Traceback (most recent call last):
  File "/home/ec2-user/intern_python/venv/lib64/python3.9/site-packages/django/core/handlers/exception.py", line 55, in inner
    response = get_response(request)
  File "/home/ec2-user/intern_python/venv/lib64/python3.9/site-packages/django/utils/deprecation.py", line 134, in __call__
    response = response or self.get_response(request)
  File "/home/ec2-user/intern_python/venv/lib64/python3.9/site-packages/django/core/handlers/exception.py", line 57, in inner
    response = response_for_exception(request, exc)
  File "/home/ec2-user/intern_python/venv/lib64/python3.9/site-packages/django/core/handlers/exception.py", line 141, in response_for_exception
    response = handle_uncaught_exception(
  File "/home/ec2-user/intern_python/venv/lib64/python3.9/site-packages/django/core/handlers/exception.py", line 182, in handle_uncaught_exception
    return debug.technical_500_response(request, *exc_info)
  File "/home/ec2-user/intern_python/venv/lib64/python3.9/site-packages/django/views/debug.py", line 67, in technical_500_response
    html = reporter.get_traceback_html()
  File "/home/ec2-user/intern_python/venv/lib64/python3.9/site-packages/django/views/debug.py", line 410, in get_traceback_html
    c = Context(self.get_traceback_data(), use_l10n=False)
  File "/home/ec2-user/intern_python/venv/lib64/python3.9/site-packages/django/views/debug.py", line 393, in get_traceback_data
    c["raising_view_name"] = get_caller(self.request)
  File "/home/ec2-user/intern_python/venv/lib64/python3.9/site-packages/django/views/debug.py", line 100, in get_caller
    resolver_match = resolve(request.path)
  File "/home/ec2-user/intern_python/venv/lib64/python3.9/site-packages/django/urls/base.py", line 24, in resolve
    return get_resolver(urlconf).resolve(path)
  File "/home/ec2-user/intern_python/venv/lib64/python3.9/site-packages/django/urls/resolvers.py", line 663, in resolve
    for pattern in self.url_patterns:
  File "/home/ec2-user/intern_python/venv/lib64/python3.9/site-packages/django/utils/functional.py", line 57, in __get__
    res = instance.__dict__[self.name] = self.func(instance)
  File "/home/ec2-user/intern_python/venv/lib64/python3.9/site-packages/django/urls/resolvers.py", line 715, in url_patterns
    patterns = getattr(self.urlconf_module, "urlpatterns", self.urlconf_module)
  File "/home/ec2-user/intern_python/venv/lib64/python3.9/site-packages/django/utils/functional.py", line 57, in __get__
    res = instance.__dict__[self.name] = self.func(instance)
  File "/home/ec2-user/intern_python/venv/lib64/python3.9/site-packages/django/urls/resolvers.py", line 708, in urlconf_module
    return import_module(self.urlconf_name)
  File "/usr/lib64/python3.9/importlib/__init__.py", line 127, in import_module
    return _bootstrap._gcd_import(name[level:], package, level)
  File "<frozen importlib._bootstrap>", line 1030, in _gcd_import
  File "<frozen importlib._bootstrap>", line 1007, in _find_and_load
  File "<frozen importlib._bootstrap>", line 986, in _find_and_load_unlocked
  File "<frozen importlib._bootstrap>", line 680, in _load_unlocked
  File "<frozen importlib._bootstrap_external>", line 850, in exec_module
  File "<frozen importlib._bootstrap>", line 228, in _call_with_frames_removed
  File "/home/ec2-user/intern_python/python/urls.py", line 4, in <module>
    from drf_spectacular.views import SpectacularAPIView, SpectacularSwaggerView
  File "/home/ec2-user/intern_python/venv/lib64/python3.9/site-packages/drf_spectacular/views.py", line 44, in <module>
    class SpectacularAPIView(APIView):
  File "/home/ec2-user/intern_python/venv/lib64/python3.9/site-packages/drf_spectacular/views.py", line 64, in SpectacularAPIView
    def get(self, request, *args, **kwargs):
  File "/home/ec2-user/intern_python/venv/lib64/python3.9/site-packages/drf_spectacular/utils.py", line 430, in decorator
    or api_settings.DEFAULT_SCHEMA_CLASS
  File "/home/ec2-user/intern_python/venv/lib64/python3.9/site-packages/rest_framework/settings.py", line 227, in __getattr__
    val = perform_import(val, attr)
  File "/home/ec2-user/intern_python/venv/lib64/python3.9/site-packages/rest_framework/settings.py", line 168, in perform_import
    return import_from_string(val, setting_name)
  File "/home/ec2-user/intern_python/venv/lib64/python3.9/site-packages/rest_framework/settings.py", line 182, in import_from_string
    raise ImportError(msg)
ImportError: Could not import 'drf_spectacular.views.SpectacularAPIView' for API setting 'DEFAULT_SCHEMA_CLASS'. ImportError: Module "drf_spectacular.views" does not define a "SpectacularAPIView" attribute/class.

During handling of the above exception, another exception occurred:

Traceback (most recent call last):
  File "/home/ec2-user/intern_python/venv/lib64/python3.9/site-packages/django/utils/module_loading.py", line 30, in import_string
    return cached_import(module_path, class_name)
  File "/home/ec2-user/intern_python/venv/lib64/python3.9/site-packages/django/utils/module_loading.py", line 16, in cached_import
    return getattr(module, class_name)
AttributeError: partially initialized module 'drf_spectacular.views' has no attribute 'SpectacularAPIView' (most likely due to a circular import)

The above exception was the direct cause of the following exception:

Traceback (most recent call last):
  File "/home/ec2-user/intern_python/venv/lib64/python3.9/site-packages/rest_framework/settings.py", line 179, in import_from_string
    return import_string(val)
  File "/home/ec2-user/intern_python/venv/lib64/python3.9/site-packages/django/utils/module_loading.py", line 32, in import_string
    raise ImportError(
ImportError: Module "drf_spectacular.views" does not define a "SpectacularAPIView" attribute/class

During handling of the above exception, another exception occurred:

Traceback (most recent call last):
  File "/home/ec2-user/intern_python/venv/lib64/python3.9/site-packages/django/core/handlers/exception.py", line 55, in inner
    response = get_response(request)
  File "/home/ec2-user/intern_python/venv/lib64/python3.9/site-packages/django/utils/deprecation.py", line 134, in __call__
    response = response or self.get_response(request)
  File "/home/ec2-user/intern_python/venv/lib64/python3.9/site-packages/django/core/handlers/exception.py", line 57, in inner
    response = response_for_exception(request, exc)
  File "/home/ec2-user/intern_python/venv/lib64/python3.9/site-packages/django/core/handlers/exception.py", line 141, in response_for_exception
    response = handle_uncaught_exception(
  File "/home/ec2-user/intern_python/venv/lib64/python3.9/site-packages/django/core/handlers/exception.py", line 182, in handle_uncaught_exception
    return debug.technical_500_response(request, *exc_info)
  File "/home/ec2-user/intern_python/venv/lib64/python3.9/site-packages/django/views/debug.py", line 67, in technical_500_response
    html = reporter.get_traceback_html()
  File "/home/ec2-user/intern_python/venv/lib64/python3.9/site-packages/django/views/debug.py", line 410, in get_traceback_html
    c = Context(self.get_traceback_data(), use_l10n=False)
  File "/home/ec2-user/intern_python/venv/lib64/python3.9/site-packages/django/views/debug.py", line 393, in get_traceback_data
    c["raising_view_name"] = get_caller(self.request)
  File "/home/ec2-user/intern_python/venv/lib64/python3.9/site-packages/django/views/debug.py", line 100, in get_caller
    resolver_match = resolve(request.path)
  File "/home/ec2-user/intern_python/venv/lib64/python3.9/site-packages/django/urls/base.py", line 24, in resolve
    return get_resolver(urlconf).resolve(path)
  File "/home/ec2-user/intern_python/venv/lib64/python3.9/site-packages/django/urls/resolvers.py", line 663, in resolve
    for pattern in self.url_patterns:
  File "/home/ec2-user/intern_python/venv/lib64/python3.9/site-packages/django/utils/functional.py", line 57, in __get__
    res = instance.__dict__[self.name] = self.func(instance)
  File "/home/ec2-user/intern_python/venv/lib64/python3.9/site-packages/django/urls/resolvers.py", line 715, in url_patterns
    patterns = getattr(self.urlconf_module, "urlpatterns", self.urlconf_module)
  File "/home/ec2-user/intern_python/venv/lib64/python3.9/site-packages/django/utils/functional.py", line 57, in __get__
    res = instance.__dict__[self.name] = self.func(instance)
  File "/home/ec2-user/intern_python/venv/lib64/python3.9/site-packages/django/urls/resolvers.py", line 708, in urlconf_module
    return import_module(self.urlconf_name)
  File "/usr/lib64/python3.9/importlib/__init__.py", line 127, in import_module
    return _bootstrap._gcd_import(name[level:], package, level)
  File "<frozen importlib._bootstrap>", line 1030, in _gcd_import
  File "<frozen importlib._bootstrap>", line 1007, in _find_and_load
  File "<frozen importlib._bootstrap>", line 986, in _find_and_load_unlocked
  File "<frozen importlib._bootstrap>", line 680, in _load_unlocked
  File "<frozen importlib._bootstrap_external>", line 850, in exec_module
  File "<frozen importlib._bootstrap>", line 228, in _call_with_frames_removed
  File "/home/ec2-user/intern_python/python/urls.py", line 4, in <module>
    from drf_spectacular.views import SpectacularAPIView, SpectacularSwaggerView
  File "/home/ec2-user/intern_python/venv/lib64/python3.9/site-packages/drf_spectacular/views.py", line 44, in <module>
    class SpectacularAPIView(APIView):
  File "/home/ec2-user/intern_python/venv/lib64/python3.9/site-packages/drf_spectacular/views.py", line 64, in SpectacularAPIView
    def get(self, request, *args, **kwargs):
  File "/home/ec2-user/intern_python/venv/lib64/python3.9/site-packages/drf_spectacular/utils.py", line 430, in decorator
    or api_settings.DEFAULT_SCHEMA_CLASS
  File "/home/ec2-user/intern_python/venv/lib64/python3.9/site-packages/rest_framework/settings.py", line 227, in __getattr__
    val = perform_import(val, attr)
  File "/home/ec2-user/intern_python/venv/lib64/python3.9/site-packages/rest_framework/settings.py", line 168, in perform_import
    return import_from_string(val, setting_name)
  File "/home/ec2-user/intern_python/venv/lib64/python3.9/site-packages/rest_framework/settings.py", line 182, in import_from_string
    raise ImportError(msg)
ImportError: Could not import 'drf_spectacular.views.SpectacularAPIView' for API setting 'DEFAULT_SCHEMA_CLASS'. ImportError: Module "drf_spectacular.views" does not define a "SpectacularAPIView" attribute/class.

During handling of the above exception, another exception occurred:

Traceback (most recent call last):
  File "/home/ec2-user/intern_python/venv/lib64/python3.9/site-packages/django/utils/module_loading.py", line 30, in import_string
    return cached_import(module_path, class_name)
  File "/home/ec2-user/intern_python/venv/lib64/python3.9/site-packages/django/utils/module_loading.py", line 16, in cached_import
    return getattr(module, class_name)
AttributeError: partially initialized module 'drf_spectacular.views' has no attribute 'SpectacularAPIView' (most likely due to a circular import)

The above exception was the direct cause of the following exception:

Traceback (most recent call last):
  File "/home/ec2-user/intern_python/venv/lib64/python3.9/site-packages/rest_framework/settings.py", line 179, in import_from_string
    return import_string(val)
  File "/home/ec2-user/intern_python/venv/lib64/python3.9/site-packages/django/utils/module_loading.py", line 32, in import_string
    raise ImportError(
ImportError: Module "drf_spectacular.views" does not define a "SpectacularAPIView" attribute/class

During handling of the above exception, another exception occurred:

Traceback (most recent call last):
  File "/home/ec2-user/intern_python/venv/lib64/python3.9/site-packages/gunicorn/workers/sync.py", line 134, in handle
    self.handle_request(listener, req, client, addr)
  File "/home/ec2-user/intern_python/venv/lib64/python3.9/site-packages/gunicorn/workers/sync.py", line 177, in handle_request
    respiter = self.wsgi(environ, resp.start_response)
  File "/home/ec2-user/intern_python/venv/lib64/python3.9/site-packages/django/core/handlers/wsgi.py", line 124, in __call__
    response = self.get_response(request)
  File "/home/ec2-user/intern_python/venv/lib64/python3.9/site-packages/django/core/handlers/base.py", line 140, in get_response
    response = self._middleware_chain(request)
  File "/home/ec2-user/intern_python/venv/lib64/python3.9/site-packages/django/core/handlers/exception.py", line 57, in inner
    response = response_for_exception(request, exc)
  File "/home/ec2-user/intern_python/venv/lib64/python3.9/site-packages/django/core/handlers/exception.py", line 141, in response_for_exception
    response = handle_uncaught_exception(
  File "/home/ec2-user/intern_python/venv/lib64/python3.9/site-packages/django/core/handlers/exception.py", line 182, in handle_uncaught_exception
    return debug.technical_500_response(request, *exc_info)
  File "/home/ec2-user/intern_python/venv/lib64/python3.9/site-packages/django/views/debug.py", line 67, in technical_500_response
    html = reporter.get_traceback_html()
  File "/home/ec2-user/intern_python/venv/lib64/python3.9/site-packages/django/views/debug.py", line 410, in get_traceback_html
    c = Context(self.get_traceback_data(), use_l10n=False)
  File "/home/ec2-user/intern_python/venv/lib64/python3.9/site-packages/django/views/debug.py", line 393, in get_traceback_data
    c["raising_view_name"] = get_caller(self.request)
  File "/home/ec2-user/intern_python/venv/lib64/python3.9/site-packages/django/views/debug.py", line 100, in get_caller
    resolver_match = resolve(request.path)
  File "/home/ec2-user/intern_python/venv/lib64/python3.9/site-packages/django/urls/base.py", line 24, in resolve
    return get_resolver(urlconf).resolve(path)
  File "/home/ec2-user/intern_python/venv/lib64/python3.9/site-packages/django/urls/resolvers.py", line 663, in resolve
    for pattern in self.url_patterns:
  File "/home/ec2-user/intern_python/venv/lib64/python3.9/site-packages/django/utils/functional.py", line 57, in __get__
    res = instance.__dict__[self.name] = self.func(instance)
  File "/home/ec2-user/intern_python/venv/lib64/python3.9/site-packages/django/urls/resolvers.py", line 715, in url_patterns
    patterns = getattr(self.urlconf_module, "urlpatterns", self.urlconf_module)
  File "/home/ec2-user/intern_python/venv/lib64/python3.9/site-packages/django/utils/functional.py", line 57, in __get__
    res = instance.__dict__[self.name] = self.func(instance)
  File "/home/ec2-user/intern_python/venv/lib64/python3.9/site-packages/django/urls/resolvers.py", line 708, in urlconf_module
    return import_module(self.urlconf_name)
  File "/usr/lib64/python3.9/importlib/__init__.py", line 127, in import_module
    return _bootstrap._gcd_import(name[level:], package, level)
  File "<frozen importlib._bootstrap>", line 1030, in _gcd_import
  File "<frozen importlib._bootstrap>", line 1007, in _find_and_load
  File "<frozen importlib._bootstrap>", line 986, in _find_and_load_unlocked
  File "<frozen importlib._bootstrap>", line 680, in _load_unlocked
  File "<frozen importlib._bootstrap_external>", line 850, in exec_module
  File "<frozen importlib._bootstrap>", line 228, in _call_with_frames_removed
  File "/home/ec2-user/intern_python/python/urls.py", line 4, in <module>
    from drf_spectacular.views import SpectacularAPIView, SpectacularSwaggerView
  File "/home/ec2-user/intern_python/venv/lib64/python3.9/site-packages/drf_spectacular/views.py", line 44, in <module>
    class SpectacularAPIView(APIView):
  File "/home/ec2-user/intern_python/venv/lib64/python3.9/site-packages/drf_spectacular/views.py", line 64, in SpectacularAPIView
    def get(self, request, *args, **kwargs):
  File "/home/ec2-user/intern_python/venv/lib64/python3.9/site-packages/drf_spectacular/utils.py", line 430, in decorator
    or api_settings.DEFAULT_SCHEMA_CLASS
  File "/home/ec2-user/intern_python/venv/lib64/python3.9/site-packages/rest_framework/settings.py", line 227, in __getattr__
    val = perform_import(val, attr)
  File "/home/ec2-user/intern_python/venv/lib64/python3.9/site-packages/rest_framework/settings.py", line 168, in perform_import
    return import_from_string(val, setting_name)
  File "/home/ec2-user/intern_python/venv/lib64/python3.9/site-packages/rest_framework/settings.py", line 182, in import_from_string
    raise ImportError(msg)
ImportError: Could not import 'drf_spectacular.views.SpectacularAPIView' for API setting 'DEFAULT_SCHEMA_CLASS'. ImportError: Module "drf_spectacular.views" does not define a "SpectacularAPIView" attribute/class.
[2025-06-14 07:19:49 +0000] [28062] [INFO] Parent changed, shutting down: <Worker 28062>
[2025-06-14 07:19:49 +0000] [28062] [INFO] Worker exiting (pid: 28062)
[2025-06-14 07:20:29 +0000] [28202] [INFO] Starting gunicorn 23.0.0
[2025-06-14 07:20:29 +0000] [28202] [INFO] Listening at: http://0.0.0.0:8000 (28202)
[2025-06-14 07:20:29 +0000] [28202] [INFO] Using worker: sync
[2025-06-14 07:20:29 +0000] [28203] [INFO] Booting worker with pid: 28203
Internal Server Error: /api/schema/
Traceback (most recent call last):
  File "/home/ec2-user/intern_python/venv/lib64/python3.9/site-packages/django/core/handlers/exception.py", line 55, in inner
    response = get_response(request)
  File "/home/ec2-user/intern_python/venv/lib64/python3.9/site-packages/django/core/handlers/base.py", line 197, in _get_response
    response = wrapped_callback(request, *callback_args, **callback_kwargs)
  File "/home/ec2-user/intern_python/venv/lib64/python3.9/site-packages/django/views/decorators/csrf.py", line 56, in wrapper_view
    return view_func(*args, **kwargs)
  File "/home/ec2-user/intern_python/venv/lib64/python3.9/site-packages/django/views/generic/base.py", line 105, in view
    return self.dispatch(request, *args, **kwargs)
  File "/home/ec2-user/intern_python/venv/lib64/python3.9/site-packages/rest_framework/views.py", line 515, in dispatch
    response = self.handle_exception(exc)
  File "/home/ec2-user/intern_python/venv/lib64/python3.9/site-packages/rest_framework/views.py", line 475, in handle_exception
    self.raise_uncaught_exception(exc)
  File "/home/ec2-user/intern_python/venv/lib64/python3.9/site-packages/rest_framework/views.py", line 486, in raise_uncaught_exception
    raise exc
  File "/home/ec2-user/intern_python/venv/lib64/python3.9/site-packages/rest_framework/views.py", line 512, in dispatch
    response = handler(request, *args, **kwargs)
  File "/home/ec2-user/intern_python/venv/lib64/python3.9/site-packages/drf_spectacular/views.py", line 84, in get
    return self._get_schema_response(request)
  File "/home/ec2-user/intern_python/venv/lib64/python3.9/site-packages/drf_spectacular/views.py", line 92, in _get_schema_response
    data=generator.get_schema(request=request, public=self.serve_public),
  File "/home/ec2-user/intern_python/venv/lib64/python3.9/site-packages/drf_spectacular/generators.py", line 285, in get_schema
    paths=self.parse(request, public),
  File "/home/ec2-user/intern_python/venv/lib64/python3.9/site-packages/drf_spectacular/generators.py", line 250, in parse
    assert isinstance(view.schema, AutoSchema), (
AssertionError: Incompatible AutoSchema used on View <class 'users.views.AdminRoleGrantView'>. Is DRF's DEFAULT_SCHEMA_CLASS pointing to "drf_spectacular.openapi.AutoSchema" or any other drf-spectacular compatible AutoSchema?
Internal Server Error: /api/schema/
Traceback (most recent call last):
  File "/home/ec2-user/intern_python/venv/lib64/python3.9/site-packages/django/core/handlers/exception.py", line 55, in inner
    response = get_response(request)
  File "/home/ec2-user/intern_python/venv/lib64/python3.9/site-packages/django/core/handlers/base.py", line 197, in _get_response
    response = wrapped_callback(request, *callback_args, **callback_kwargs)
  File "/home/ec2-user/intern_python/venv/lib64/python3.9/site-packages/django/views/decorators/csrf.py", line 56, in wrapper_view
    return view_func(*args, **kwargs)
  File "/home/ec2-user/intern_python/venv/lib64/python3.9/site-packages/django/views/generic/base.py", line 105, in view
    return self.dispatch(request, *args, **kwargs)
  File "/home/ec2-user/intern_python/venv/lib64/python3.9/site-packages/rest_framework/views.py", line 515, in dispatch
    response = self.handle_exception(exc)
  File "/home/ec2-user/intern_python/venv/lib64/python3.9/site-packages/rest_framework/views.py", line 475, in handle_exception
    self.raise_uncaught_exception(exc)
  File "/home/ec2-user/intern_python/venv/lib64/python3.9/site-packages/rest_framework/views.py", line 486, in raise_uncaught_exception
    raise exc
  File "/home/ec2-user/intern_python/venv/lib64/python3.9/site-packages/rest_framework/views.py", line 512, in dispatch
    response = handler(request, *args, **kwargs)
  File "/home/ec2-user/intern_python/venv/lib64/python3.9/site-packages/drf_spectacular/views.py", line 84, in get
    return self._get_schema_response(request)
  File "/home/ec2-user/intern_python/venv/lib64/python3.9/site-packages/drf_spectacular/views.py", line 92, in _get_schema_response
    data=generator.get_schema(request=request, public=self.serve_public),
  File "/home/ec2-user/intern_python/venv/lib64/python3.9/site-packages/drf_spectacular/generators.py", line 285, in get_schema
    paths=self.parse(request, public),
  File "/home/ec2-user/intern_python/venv/lib64/python3.9/site-packages/drf_spectacular/generators.py", line 250, in parse
    assert isinstance(view.schema, AutoSchema), (
AssertionError: Incompatible AutoSchema used on View <class 'users.views.AdminRoleGrantView'>. Is DRF's DEFAULT_SCHEMA_CLASS pointing to "drf_spectacular.openapi.AutoSchema" or any other drf-spectacular compatible AutoSchema?
[2025-06-14 07:23:04 +0000] [28203] [INFO] Parent changed, shutting down: <Worker 28203>
[2025-06-14 07:23:04 +0000] [28203] [INFO] Worker exiting (pid: 28203)
[2025-06-14 07:23:59 +0000] [28337] [INFO] Starting gunicorn 23.0.0
[2025-06-14 07:23:59 +0000] [28337] [INFO] Listening at: http://0.0.0.0:8000 (28337)
[2025-06-14 07:23:59 +0000] [28337] [INFO] Using worker: sync
[2025-06-14 07:23:59 +0000] [28338] [INFO] Booting worker with pid: 28338
/home/ec2-user/intern_python/users/views.py: Error [AdminRoleGrantView]: unable to guess serializer. This is graceful fallback handling for APIViews. Consider using GenericAPIView as view base class, if view is under your control. Either way you may want to add a serializer_class (or method). Ignoring view for now.
/home/ec2-user/intern_python/users/views.py: Error [LoginView]: unable to guess serializer. This is graceful fallback handling for APIViews. Consider using GenericAPIView as view base class, if view is under your control. Either way you may want to add a serializer_class (or method). Ignoring view for now.
/home/ec2-user/intern_python/users/views.py: Error [ProfileView]: unable to guess serializer. This is graceful fallback handling for APIViews. Consider using GenericAPIView as view base class, if view is under your control. Either way you may want to add a serializer_class (or method). Ignoring view for now.
/home/ec2-user/intern_python/users/views.py: Error [SignupView]: unable to guess serializer. This is graceful fallback handling for APIViews. Consider using GenericAPIView as view base class, if view is under your control. Either way you may want to add a serializer_class (or method). Ignoring view for now.
Not Found: /
